Workbook

Sheet 本金与余额
B2: 序号 | C2: 姓名 | D2: R/H | E2: R/H余额
B3: 1 | C3: 徐伟伟 | D3: 1000000
B4: 2 | C4: 何凤 | D4: 1000000
B5: 3 | C5: 钟荣辉 | D5: 1000000
B6: 4 | C6: 宋倩 | D6: 1000000
B7: 5 | C7: 张咏博 | D7: 1000000
B8: 6 | C8: 钱虹语 | D8: 1000000
B9: 7 | C9: 邹俊峰 | D9: 1000000
B10: 8 | C10: 骆怡锋 | D10: 1000000
B11: 9 | C11: 王金花 | D11: 1000000
B12: 10 | C12: 顺道 | D12: 1000000
B13: 11 | C13: 候闯振 | D13: 1000000
B14: 12 | C14: 周金英 | D14: 1000000
... B38: 36 | C38: 李生 | D38: 1000000

Sheet 伟伟
A1: back | D1: 操盘：徐伟伟
D2: 时间 | E2: 市场 | F2: 企业 | G2: 股票代码 | H2: 操作 | I2: 数量 | J2: 平均买价 | K2: 成本 | L2: 买卖价格 | M2: 市值
C3: 1 | D3: 45136 | E3: HK | F3: 腾讯集团 | G3: 00700 | H3: 买入 | I3: 200 | L3: 350.4 | M3: =L3*I3 -> 70080
C4: 2 | D4: 45171 | E4: HK | F4: 腾讯集团 | G4: 00700 | H4: 卖出 | I4: -200 | L4: 325 | M4: =L4*I4 -> -65000
C5: 3 | D5: 45136 | E5: HK | F5: 东方甄选 | G5: 1797 | H5: 买入 | I5: 1000 | L5: 38.9 | M5: =L5*I5 -> 38900
C6: 4 | D6: 45290 | E6: HK | F6: 东方甄选 | G6: 1797 | H6: 卖出 | I6: -1000 | L6: 27.8 | M6: =L6*I6 -> -27800
C7: 5 | D7: 45171 | E7: HK | F7: 东方甄选 | G7: 1797 | H7: 买入 | I7: 500 | L7: 39.75 | M7: =L7*I7 -> 19875
C8: 6 | D8: 45241 | E8: HK | F8: 东方甄选 | G8: 1797 | H8: 卖出 | I8: -500 | L8: 29.6 | M8: =L8*I8 -> -14800
C9: 7 | D9: 45150 | E9: HK | F9: 京东集团 | G9: 9618 | H9: 买入 | I9: 1000 | L9: 146.1 | M9: =L9*I9 -> 146100
C10: 8 | D10: 45241 | E10: HK | F10: 京东集团 | G10: 9618 | H10: 卖出 | I10: -400 | L10: 99 | M10: =L10*I10 -> -39600
C11: 9 | D11: 45346 | E11: HK | F11: 京东集团 | G11: 9618 | H11: 卖出 | I11: -600 | L11: 93.75 | M11: =L11*I11 -> -56250
C12: 10 | D12: 45136 | E12: HK | F12: 比亚迪 | G12: 1211 | H12: 买入 | I12: 200 | L12: 271.2 | M12: =L12*I12 -> 54240
C13: 11 | D13: 45346 | E13: HK | F13: 比亚迪 | G13: 1211 | H13: 卖出 | I13: -200 | L13: 185.2 | M13: =L13*I13 -> -37040
C14: 12 | D14: 45150 | E14: HK | F14: 舜宇光学科技 | G14: 2382 | H14: 买入 | I14: 2382 | L14: 68.95 | M14: =L14*I14 -> 164238.9
C15: 13 | D15: 45171 | E15: HK | F15: 舜宇光学科技 | G15: 2382 | H15: 买入 | I15: 500 | L15: 64.1 | M15: =L15*I15 -> 32050
C16: 14 | D16: 45353 | E16: HK | F16: 舜宇光学科技 | G16: 2382 | H16: 卖出 | I16: -2882 | L16: 50.9 | M16: =L16*I16 -> -146693.8
C17: 15 | D17: 45213 | E17: US | F17: 小鹏汽车 | G17: XPEV | H17: 买入 | I17: 500 | L17: 125.892 | M17: =L17*I17 -> 62946
C18: 16 | D18: 45360 | E18: US | F18: 小鹏汽车 | G18: XPEV | H18: 卖出 | I18: -500 | L18: 74.256 | M18: =L18*I18 -> -37128
C19: 20 | D19: 45241 | E19: CN | F19: 爱美客 | G19: 300896 | H19: 买入 | I19: 500 | L19: 326.85 | M19: =L19*I19 -> 163425
D20: 45416 | E20: CN | F20: 爱美客 | G20: 300896 | H20: 送 | I20: 200 | L20: 0 | M20: =L20*I20 -> 0
D21: 45423 | E21: CN | F21: 爱美客 | G21: 300896 | H21: 卖出 | I21: -700 | L21: 215.54 | M21: =L21*I21 -> -150878
D22: 45423 | E22: US | F22: 极氪 | G22: ZK | H22: 买入 | I22: 80 | L22: 220.428 | M22: =L22*I22 -> 17634.24
D23: 45430 | E23: US | F23: 极氪 | G23: ZK | H23: 卖出 | I23: -80 | L23: 202.8 | M23: =L23*I23 -> -16224
D24: 45430 | E24: HK | F24: 中国中免 | G24: 1880 | H24: 买入 | I24: 200 | L24: 74.6 | M24: =L24*I24 -> 14920
D25: 45451 | E25: HK | F25: 中国中免 | G25: 1880 | H25: 卖出 | I25: -200 | L25: 63.1 | M25: =L25*I25 -> -12620
D26: 45430 | E26: US | F26: 亚马逊 | G26: AMZN | H26: 买入 | I26: 20 | L26: 1440.66 | M26: =L26*I26 -> 28813.2
D27: 45458 | E27: US | F27: 亚马逊 | G27: AMZN | H27: 卖出 | I27: -10 | L27: 1432.548 | M27: =L27*I27 -> -14325.48
D28: 45472 | E28: US | F28: 亚马逊 | G28: AMZN | H28: 卖出 | I28: -10 | L28: 1507.35 | M28: =L28*I28 -> -15073.5
D29: 45430 | E29: US | F29: 谷歌 | G29: GOOGL | H29: 买入 | I29: 30 | L29: 1373.268 | M29: =L29*I29 -> 41198.04
D30: 45451 | E30: US | F30: 微软 | G30: MSFT | H30: 买入 | I30: 12 | L30: 3306.03 | M30: =L30*I30 -> 39672.36
D31: 45486 | E31: US | F31: 微软 | G31: MSFT | H31: 买入 | I31: 2 | L31: 3537.69 | M31: =L31*I31 -> 7075.38
D32: 45493 | E32: US | F32: 微软 | G32: MSFT | H32: 卖出 | I32: -14 | L32: 3409.458 | M32: =L32*I32 -> -47732.412
D33: 45556 | E33: US | F33: 微软 | G33: MSFT | H33: 买入 | I33: 13 | L33: 3395.106 | M33: =L33*I33 -> 44136.378
D34: 45577 | E34: US | F34: 微软 | G34: MSFT | H34: 卖出 | I34: -5 | L34: 3247.296 | M34: =L34*I34 -> -16236.48
D35: 45633 | E35: US | F35: 微软 | G35: MSFT | H35: 卖出 | I35: -8 | L35: 3459.846 | M35: =L35*I35 -> -27678.768
D36: 45633 | E36: US | F36: 谷歌 | G36: GOOGL | H36: 卖出 | I36: -30 | L36: 1362.738 | M36: =L36*I36 -> -40882.14
C37: 17 | D37: 45136 | E37: US | F37: 拼多多 | G37: PDD | H37: 买入 | I37: 50 | L37: 696.93 | M37: =L37*I37 -> 34846.5
C38: 18 | D38: 45241 | E38: US | F38: 诺和诺德 | G38: NVO | H38: 买入 | I38: 150 | L38: 789.282 | M38: =L38*I38 -> 118392.3
C39: 19 | D39: 45241 | E39: CN | F39: 宁德时代 | G39: 300750 | H39: 买入 | I39: 800 | L39: 189.03 | M39: =L39*I39 -> 151224
C40: 21 | D40: 45290 | E40: US | F40: 拼多多 | G40: PDD | H40: 买入 | I40: 30 | L40: 1141.218 | M40: =L40*I40 -> 34236.54
...

Sheet 何凤
A1: back | D1: 操盘：何凤
D2: 时间 | E2: 市场 | F2: 企业 | G2: 股票代码 | H2: 操作 | I2: 数量 | J2: 平均买价 | K2: 成本 | L2: 买卖价格 | M2: 市值
D3: 45479 | E3: CN | F3: 百纳千成 | G3: 300291 | H3: 卖出 | I3: -1000 | L3: 4.2 | M3: =L3*I3 -> -4200
C4: 3 | D4: 45241 | E4: CN | F4: 百纳千成 | G4: 300291 | H4: 买入 | I4: 5000 | L4: 7.81 | M4: =L4*I4 -> 39050
C5: 6 | D5: 45402 | E5: CN | F5: 百纳千成 | G5: 300291 | H5: 卖出 | I5: -4000 | L5: 4.56 | M5: =L5*I5 -> -18240
C6: 8 | D6: 45402 | E6: HK | F6: 理想汽车 | G6: 2015 | H6: 卖出 | I6: -500 | L6: 106.3 | M6: =L6*I6 -> -53150
C7: 4 | D7: 45304 | E7: HK | F7: 理想汽车 | G7: 2015 | H7: 买入 | I7: 1000 | L7: 126.1 | M7: =L7*I7 -> 126100
D8: 45479 | E8: HK | F8: 理想汽车 | G8: 2015 | H8: 卖出 | I8: -500 | L8: 79.25 | M8: =L8*I8 -> -39625
D9: 45479 | E9: CN | F9: 贝肯能源 | G9: 002828 | H9: 卖出 | I9: -500 | L9: 8.37 | M9: =L9*I9 -> -4185
D10: 45402 | E10: CN | F10: 贝肯能源 | G10: 002828 | H10: 买入 | I10: 500 | L10: 11.69 | M10: =L10*I10 -> 5845
D11: 45402 | E11: CN | F11: 中信海直 | G11: 000099 | H11: 买入 | I11: 500 | L11: 22.26 | M11: =L11*I11 -> 11130
D12: 45479 | E12: CN | F12: 中信海直 | G12: 000099 | H12: 卖出 | I12: -500 | L12: 15.46 | M12: =L12*I12 -> -7730
C13: 1 | D13: 45150 | E13: CN | F13: 比亚迪 | G13: 002594 | H13: 买入 | I13: 2000 | L13: 259.25 | M13: =L13*I13 -> 518500
C14: 2 | D14: 45192 | E14: CN | F14: 比亚迪 | G14: 002594 | H14: 买入 | I14: 500 | L14: 245.05 | M14: =L14*I14 -> 122525
C15: 5 | D15: 45402 | E15: CN | F15: 比亚迪 | G15: 002594 | H15: 卖出 | I15: -1000 | L15: 210.13 | M15: =L15*I15 -> -210130
D16: 45402 | E16: US | F16: 特斯拉 | G16: TSLA | H16: 买入 | I16: 100 | L16: 1146.99 | M16: =L16*I16 -> 114699
C17: 9 | D17: 45402 | E17: CN | F17: 赛力斯 | G17: 601127 | H17: 买入 | I17: 2000 | L17: 95.48 | M17: =L17*I17 -> 190960
D18: 45430 | E18: US | F18: 强生 | G18: JNJ | H18: 买入 | I18: 100 | L18: 1206.192 | M18: =L18*I18 -> 120619.2
D19: 45514 | E19: US | F19: 特斯拉 | G19: TSLA | H19: 买入 | I19: 50 | L19: 1560 | M19: =L19*I19 -> 78000
D20: 45535 | E20: CN | F20: 比亚迪 | G20: 002594 | H20: 卖出 | I20: -1500 | L20: 249.42 | M20: =L20*I20 -> -374130
D21: 45535 | E21: US | F21: 特斯拉 | G21: TSLA | H21: 卖出 | I21: -150 | L21: 1670.058 | M21: =L21*I21 -> -250508.7
D22: 45535 | E22: CN | F22: 赛力斯 | G22: 601127 | H22: 卖出 | I22: -2000 | L22: 76.52 | M22: =L22*I22 -> -153040
D23: 45535 | E23: US | F23: 强生 | G23: JNJ | H23: 卖出 | I23: -100 | L23: 1293.708 | M23: =L23*I23 -> -129370.8
D24: 45535 | E24: CN | F24: 日久光电 | G24: 003015 | H24: 买入 | I24: 33000 | L24: 13.22 | M24: =L24*I24 -> 436260
D25: 45535 | E25: CN | F25: 奋达科技 | G25: 002681 | H25: 买入 | I25: 72700 | L25: 4.81 | M25: =L25*I25 -> 349687
D26: 45535 | E26: CN | F26: 科森科技 | G26: 603626 | H26: 买入 | I26: 15948 | L26: 8.21 | M26: =L26*I26 -> 130933.08
D27: 45542 | E27: CN | F27: 日久光电 | G27: 003015 | H27: 卖出 | I27: -33000 | L27: 11.87 | M27: =L27*I27 -> -391710
D28: 45542 | E28: CN | F28: 奋达科技 | G28: 002681 | H28: 卖出 | I28: -72700 | L28: 4 | M28: =L28*I28 -> -290800
D29: 45542 | E29: CN | F29: 大众交通 | G29: 600611 | H29: 买入 | I29: 43995 | L29: 11.44 | M29: =L29*I29 -> 503302.8
... D107: 46011 | E107: CN | F107: 航天发展 | G107: 000547 | H107: 买入 | I107: 9000 | L107: 22.3 | M107: =L107*I107 -> 200700
M108: =L108*I108 -> 0
M109: =L109*I109 -> 0
M110: =L110*I110 -> 0
M111: =L111*I111 -> 0
D112: 累计净买入 | M112: =SUM(M3:M111) -> 999652.18
D113: 时间 | E113: 市场 | F113: 企业 | G113: 股票代码 | H113: 状态 | I113: 数量 | J113: 平均买价 | K113: 成本 | L113: 当前价格 | M113: 市值
D114: =全班!$R$1 -> 46011 | E114: US | F114: 英伟达 | G114: NVDA | H114: 持有 | I114: =SUMIFS($I$99:$I$112,$G$99:$G$112,G114) -> 200 | J114: =K114/I114 -> 1380.6 | K114: =SUMIFS($M$99:$M$111,$G$99:$G$111,G114) -> 276120 | L114: =VLOOKUP(G114,股价!C:D,2,FALSE) -> 1411.722 | M114: =IFERROR(I114*L114,0) -> 282344.4
D115: =全班!$R$1 -> 46011 | E115: US | F115: 小鹏汽车 | G115: XPEV | H115: 持有 | I115: =SUMIFS($I$99:$I$112,$G$99:$G$112,G115) -> 1000 | J115: =K115/I115 -> 148.122 | K115: =SUMIFS($M$99:$M$111,$G$99:$G$111,G115) -> 148122 | L115: =VLOOKUP(G115,股价!C:D,2,FALSE) -> 154.908 | M115: =IFERROR(I115*L115,0) -> 154908
D116: =全班!$R$1 -> 46011 | E116: CN | F116: 航天电机 | G116: 600151 | H116: 持有 | I116: =SUMIFS($I$99:$I$112,$G$99:$G$112,G116) -> 5000 | J116: =K116/I116 -> 15.4 | K116: =SUMIFS($M$99:$M$111,$G$99:$G$111,G116) -> 77000 | L116: =VLOOKUP(G116,股价!C:D,2,FALSE) -> 18.88 | M116: =IFERROR(I116*L116,0) -> 94400
D117: =全班!$R$1 -> 46011 | E117: CN | F117: 海南瑞泽 | G117: 002596 | H117: 持有 | I117: =SUMIFS($I$99:$I$112,$G$99:$G$112,G117) -> 40500 | J117: =K117/I117 -> 5.35 | K117: =SUMIFS($M$99:$M$111,$G$99:$G$111,G117) -> 216675 | L117: =VLOOKUP(G117,股价!C:D,2,FALSE) -> 5.35 | M117: =IFERROR(I117*L117,0) -> 216675
...

Sheet 荣辉 
A1: back | D1: 操盘：钟荣辉
D2: 时间 | E2: 市场 | F2: 企业 | G2: 股票代码 | H2: 操作 | I2: 数量 | J2: 平均买价 | K2: 成本 | L2: 买卖价格 | M2: 市值
C3: 2 | D3: 45164 | E3: HK | F3: 东方甄选 | G3: 1797 | H3: 买入 | I3: 1000 | L3: 43.15 | M3: =L3*I3 -> 43150
C4: 6 | D4: 45227 | E4: HK | F4: 东方甄选 | G4: 1797 | H4: 卖出 | I4: -500 | L4: 32.4 | M4: =L4*I4 -> -16200
C5: 9 | D5: 45227 | E5: HK | F5: 李宁 | G5: 2331 | H5: 买入 | I5: 500 | L5: 24.9 | M5: =L5*I5 -> 12450
C6: 10 | D6: 45234 | E6: HK | F6: 小米集团 | G6: 1810 | H6: 买入 | I6: 10000 | L6: 15.24 | M6: =L6*I6 -> 152400
C7: 12 | D7: 45276 | E7: HK | F7: 东方甄选 | G7: 1797 | H7: 买入 | I7: 500 | L7: 26.25 | M7: =L7*I7 -> 13125
D8: 45367 | E8: HK | F8: 东方甄选 | G8: 1797 | H8: 卖出 | I8: -1000 | L8: 23.9 | M8: =L8*I8 -> -23900
D9: 45367 | E9: HK | F9: 李宁 | G9: 2331 | H9: 卖出 | I9: -500 | L9: 20.7 | M9: =L9*I9 -> -10350
D10: 45367 | E10: HK | F10: 小米集团 | G10: 1810 | H10: 卖出 | I10: -10000 | L10: 14.54 | M10: =L10*I10 -> -145400
C11: 8 | D11: 45227 | E11: CN | F11: 赛力斯 | G11: 601127 | H11: 买入 | I11: 500 | L11: 79.81 | M11: =L11*I11 -> 39905
C12: 11 | D12: 45234 | E12: HK | F12: 中兴通讯 | G12: 763 | H12: 买入 | I12: 2000 | L12: 18.04 | M12: =L12*I12 -> 36080
D13: 45367 | E13: CN | F13: 赛力斯 | G13: 601127 | H13: 卖出 | I13: -500 | L13: 98.45 | M13: =L13*I13 -> -49225
D14: 45367 | E14: HK | F14: 中兴通讯 | G14: 763 | H14: 卖出 | I14: -2000 | L14: 17.12 | M14: =L14*I14 -> -34240
C15: 5 | D15: 45192 | E15: US | F15: 可口可乐 | G15: KO | H15: 买入 | I15: 500 | L15: 449.28 | M15: =L15*I15 -> 224640
D16: 45374 | E16: US | F16: 可口可乐 | G16: KO | H16: 卖出 | I16: -300 | L16: 471.822 | M16: =L16*I16 -> -141546.6
D17: 45409 | E17: US | F17: 可口可乐 | G17: KO | H17: 卖出 | I17: -100 | L17: 481.572 | M17: =L17*I17 -> -48157.2
D18: 45437 | E18: US | F18: 可口可乐 | G18: KO | H18: 卖出 | I18: -100 | L18: 483.6 | M18: =L18*I18 -> -48360
C19: 1 | D19: 45164 | E19: CN | F19: 比亚迪 | G19: 002594 | H19: 买入 | I19: 1000 | L19: 232.6 | M19: =L19*I19 -> 232600
D20: 45374 | E20: CN | F20: 比亚迪 | G20: 002594 | H20: 卖出 | I20: -1000 | L20: 216.95 | M20: =L20*I20 -> -216950
C21: 3 | D21: 45178 | E21: US | F21: 京东 | G21: JD | H21: 买入 | I21: 500 | L21: 252.72 | M21: =L21*I21 -> 126360
C22: 4 | D22: 45185 | E22: US | F22: 京东 | G22: JD | H22: 买入 | I22: 500 | L22: 246.246 | M22: =L22*I22 -> 123123
C23: 7 | D23: 45227 | E23: US | F23: 京东 | G23: JD | H23: 卖出 | I23: -500 | L23: 200.07 | M23: =L23*I23 -> -100035
D24: 45374 | E24: US | F24: 京东 | G24: JD | H24: 卖出 | I24: -500 | L24: 206.7 | M24: =L24*I24 -> -103350
D25: 45367 | E25: US | F25: 特斯拉 | G25: TSLA | H25: 买入 | I25: 50 | L25: 1275.846 | M25: =L25*I25 -> 63792.3
D26: 45367 | E26: US | F26: 拼多多 | G26: PDD | H26: 买入 | I26: 50 | L26: 965.172 | M26: =L26*I26 -> 48258.6
D27: 45367 | E27: US | F27: 英伟达 | G27: NVDA | H27: 买入 | I27: 20 | L27: 6851.286 | M27: =L27*I27 -> 137025.72
D28: 45367 | E28: US | F28: 谷歌-A | G28: GOOGL | H28: 买入 | I28: 50 | L28: 1101.204 | M28: =L28*I28 -> 55060.2
D29: 45367 | E29: US | F29: 脸书 | G29: Meta | H29: 买入 | I29: 10 | L29: 3775.98 | M29: =L29*I29 -> 37759.8
D30: 45374 | E30: US | F30: 英伟达 | G30: NVDA | H30: 买入 | I30: 10 | L30: 7354.542 | M30: =L30*I30 -> 73545.42
D31: 45374 | E31: US | F31: 脸书 | G31: Meta | H31: 买入 | I31: 20 | L31: 3974.724 | M31: =L31*I31 -> 79494.48
D32: 45374 | E32: US | F32: 阿斯麦 | G32: ASML | H32: 买入 | I32: 10 | L32: 7643.688 | M32: =L32*I32 -> 76436.88
D33: 45374 | E33: US | F33: 诺和诺德 | G33: NVO | H33: 买入 | I33: 50 | L33: 1004.328 | M33: =L33*I33 -> 50216.4
D34: 45374 | E34: US | F34: 高通 | G34: QCOM | H34: 买入 | I34: 30 | L34: 1326.78 | M34: =L34*I34 -> 39803.4
D35: 45374 | E35: US | F35: 台积电 | G35: TSM | H35: 买入 | I35: 30 | L35: 1096.212 | M35: =L35*I35 -> 32886.36
... D77: 45528 | E77: US | F77: 诺和诺德 | G77: NVO | H77: 卖出 | I77: -20 | L77: 1068.366 | M77: =L77*I77 -> -21367.32
D78: =全班!$R$1 -> 46011 | E78: US | F78: 高通 | G78: QCOM | H78: 买入 | I78: 20 | L78: 1404.39 | M78: =L78*I78 -> 28087.8
D79: 45528 | E79: US | F79: 高通 | G79: QCOM | H79: 卖出 | I79: -20 | L79: 1353.3 | M79: =L79*I79 -> -27066
D80: 45500 | E80: US | F80: 微软 | G80: MSFT | H80: 买入 | I80: 15 | L80: 3317.106 | M80: =L80*I80 -> 49756.59
D81: 45528 | E81: US | F81: 微软 | G81: MSFT | H81: 卖出 | I81: -15 | L81: 3250.962 | M81: =L81*I81 -> -48764.43
...

Sheet 宋倩
A1: back | D1: 操盘：宋倩
D2: 时间 | E2: 市场 | F2: 企业 | G2: 股票代码 | H2: 操作 | I2: 数量 | J2: 平均买价 | K2: 成本 | L2: 买卖价格 | M2: 市值
C3: 3 | D3: 45213 | E3: HK | F3: 比亚迪股份 | G3: 1211 | H3: 买入 | I3: 1000 | L3: 243.4 | M3: =L3*I3 -> 243400
C4: 6 | D4: 45269 | E4: HK | F4: 比亚迪股份 | G4: 1211 | H4: 买入 | I4: 1000 | L4: 210.8 | M4: =L4*I4 -> 210800
D5: 45409 | E5: HK | F5: 比亚迪股份 | G5: 1211 | H5: 卖出 | I5: -1000 | L5: 212.8 | M5: =L5*I5 -> -212800
D6: 45416 | E6: HK | F6: 比亚迪股份 | G6: 1211 | H6: 卖出 | I6: -1000 | L6: 226.4 | M6: =L6*I6 -> -226400
D7: 45409 | E7: US | F7: 苹果 | G7: AAPL | H7: 买入 | I7: 20 | L7: 1320.54 | M7: =L7*I7 -> 26410.8
D8: 45416 | E8: US | F8: 苹果 | G8: AAPL | H8: 卖出 | I8: -20 | L8: 1430.364 | M8: =L8*I8 -> -28607.28
C9: 2 | D9: 45213 | E9: HK | F9: 东方甄选 | G9: 1797 | H9: 买入 | I9: 1000 | L9: 35.05 | M9: =L9*I9 -> 35050
C10: 5 | D10: 45220 | E10: HK | F10: 东方甄选 | G10: 1797 | H10: 卖出 | I10: -300 | L10: 30.25 | M10: =L10*I10 -> -9075
C11: 8 | D11: 45276 | E11: HK | F11: 东方甄选 | G11: 1797 | H11: 买入 | I11: 2000 | L11: 26.25 | M11: =L11*I11 -> 52500
D12: 45416 | E12: HK | F12: 东方甄选 | G12: 1797 | H12: 卖出 | I12: -2500 | L12: 17.96 | M12: =L12*I12 -> -44900
D13: 45479 | E13: HK | F13: 东方甄选 | G13: 1797 | H13: 卖出 | I13: -200 | L13: 12.56 | M13: =L13*I13 -> -2512
D14: 45430 | E14: US | F14: 长江基建集团 | G14: CKISY | H14: 买入 | I14: 50 | L14: 229.554 | M14: =L14*I14 -> 11477.7
D15: 45479 | E15: US | F15: 长江基建集团 | G15: CKISY | H15: 卖出 | I15: -50 | L15: 216.06 | M15: =L15*I15 -> -10803
D16: 45409 | E16: US | F16: 安森美半导体 | G16: ON | H16: 买入 | I16: 50 | L16: 530.868 | M16: =L16*I16 -> 26543.4
D17: 45409 | E17: US | F17: 台积电 | G17: TSM | H17: 买入 | I17: 30 | L17: 1078.74 | M17: =L17*I17 -> 32362.2
D18: 45416 | E18: US | F18: 安森美半导体 | G18: ON | H18: 买入 | I18: 150 | L18: 548.886 | M18: =L18*I18 -> 82332.9
D19: 45416 | E19: US | F19: 台积电 | G19: TSM | H19: 买入 | I19: 70 | L19: 1104.168 | M19: =L19*I19 -> 77291.76
D20: 45416 | E20: US | F20: 英伟达 | G20: NVDA | H20: 买入 | I20: 5 | L20: 6925.542 | M20: =L20*I20 -> 34627.71
D21: 45416 | E21: US | F21: 微软 | G21: MSFT | H21: 买入 | I21: 10 | L21: 3171.948 | M21: =L21*I21 -> 31719.48
D22: 45416 | E22: US | F22: 脸书 | G22: Meta | H22: 买入 | I22: 20 | L22: 3525.288 | M22: =L22*I22 -> 70505.76
D23: 45430 | E23: HK | F23: 中银香港 | G23: 02388 | H23: 买入 | I23: 100 | L23: 25.85 | M23: =L23*I23 -> 2585
D24: 45430 | E24: US | F24: 台积电 | G24: TSM | H24: 买入 | I24: 50 | L24: 1183.104 | M24: =L24*I24 -> 59155.2
D25: 45430 | E25: US | F25: 微软 | G25: MSFT | H25: 买入 | I25: 5 | L25: 3277.638 | M25: =L25*I25 -> 16388.19
... D56: 45913 | E56: US | F56: 亚马逊 | G56: AMZN | H56: 卖出 | I56: -10 | L56: 1779.57 | M56: =L56*I56 -> -17795.7
C57: 1 | D57: 45213 | E57: US | F57: 特斯拉 | G57: TSLA | H57: 买入 | I57: 100 | L57: 1958.736 | M57: =L57*I57 -> 195873.6
C58: 4 | D58: 45220 | E58: US | F58: 特斯拉 | G58: TSLA | H58: 买入 | I58: 30 | L58: 1653.522 | M58: =L58*I58 -> 49605.66
C59: 7 | D59: 45276 | E59: US | F59: 特斯拉 | G59: TSLA | H59: 卖出 | I59: -50 | L59: 1977.3 | M59: =L59*I59 -> -98865
C60: 9 | D60: 45311 | E60: US | F60: 特斯拉 | G60: TSLA | H60: 买入 | I60: 50 | L60: 1655.082 | M60: =L60*I60 -> 82754.1
D61: 45318 | E61: US | F61: 特斯拉 | G61: TSLA | H61: 买入 | I61: 100 | L61: 1429.35 | M61: =L61*I61 -> 142935
D62: 45409 | E62: US | F62: 特斯拉 | G62: TSLA | H62: 买入 | I62: 80 | L62: 1312.662 | M62: =L62*I62 -> 105012.96
D63: 45416 | E63: US | F63: 特斯拉 | G63: TSLA | H63: 买入 | I63: -60 | L63: 1413.282 | M63: =L63*I63 -> -84796.92
D64: 45430 | E64: US | F64: 特斯拉 | G64: TSLA | H64: 卖出 | I64: -50 | L64: 1384.188 | M64: =L64*I64 -> -69209.4
D65: 45437 | E65: US | F65: 特斯拉 | G65: TSLA | H65: 卖出 | I65: -30 | L65: 1398.072 | M65: =L65*I65 -> -41942.16
D66: 45472 | E66: US | F66: 特斯拉 | G66: TSLA | H66: 卖出 | I66: -120 | L66: 1543.464 | M66: =L66*I66 -> -185215.68
D67: 45479 | E67: US | F67: 特斯拉 | G67: TSLA | H67: 卖出 | I67: -20 | L67: 1961.856 | M67: =L67*I67 -> -39237.12
D68: 45913 | E68: US | F68: 特斯拉 | G68: TSLA | H68: 卖出 | I68: -15 | L68: 3088.332 | M68: =L68*I68 -> -46324.98
D69: 45920 | E69: US | F69: 亚马逊 | G69: AMZN | H69: 买入 | I69: 20 | L69: 1805.544 | M69: =L69*I69 -> 36110.88
D70: 45920 | E70: US | F70: 脸书 | G70: Meta | H70: 买入 | I70: 15 | L70: 6071.364 | M70: =L70*I70 -> 91070.46
...

Sheet 咏博
A1: back | D1: 操盘：张咏博
D2: 时间 | E2: 市场 | F2: 企业 | G2: 股票代码 | H2: 操作 | I2: 数量 | J2: 平均买价 | K2: 成本 | L2: 买卖价格 | M2: 市值
C3: 5 | D3: 45171 | E3: CN | F3: 五粮液 | G3: 000858 | H3: 买入 | I3: 100 | L3: 159.74 | M3: =L3*I3 -> 15974
D4: 45290 | E4: CN | F4: 五粮液 | G4: 000858 | H4: 卖出 | I4: -100 | L4: 140.31 | M4: =L4*I4 -> -14031
C5: 2 | D5: 45157 | E5: US | F5: 小鹏汽车 | G5: XPEV | H5: 买入 | I5: 1000 | L5: 116.844 | M5: =L5*I5 -> 116844
C6: 3 | D6: 45157 | E6: HK | F6: 携程集团 | G6: 9961 | H6: 买入 | I6: 100 | L6: 299.6 | M6: =L6*I6 -> 29960
D7: 45318 | E7: US | F7: 小鹏汽车 | G7: XPEV | H7: 卖出 | I7: -1000 | L7: 69.966 | M7: =L7*I7 -> -69966
D8: 45318 | E8: HK | F8: 携程集团 | G8: 9961 | H8: 卖出 | I8: -100 | L8: 290.2 | M8: =L8*I8 -> -29020
D9: 45318 | E9: HK | F9: 东方甄选 | G9: 1797 | H9: 卖出 | I9: -1000 | L9: 22.2 | M9: =L9*I9 -> -22200
C10: 6 | D10: 45171 | E10: HK | F10: 东方甄选 | G10: 1797 | H10: 买入 | I10: 1000 | L10: 39.75 | M10: =L10*I10 -> 39750
C11: 7 | D11: 45220 | E11: HK | F11: 东方甄选 | G11: 1797 | H11: 卖出 | I11: -500 | L11: 30.25 | M11: =L11*I11 -> -15125
C12: 9 | D12: 45247 | E12: HK | F12: 东方甄选 | G12: 1797 | H12: 买入 | I12: 500 | L12: 28.65 | M12: =L12*I12 -> 14325
D13: 45423 | E13: US | F13: 极氪 | G13: ZK | H13: 买入 | I13: 50 | L13: 220.428 | M13: =L13*I13 -> 11021.4
D14: 45437 | E14: US | F14: 极氪 | G14: ZK | H14: 卖出 | I14: -50 | L14: 182.364 | M14: =L14*I14 -> -9118.2
D15: 45374 | E15: HK | F15: 小米集团 | G15: 1810 | H15: 买入 | I15: 10000 | L15: 14.8 | M15: =L15*I15 -> 148000
D16: 45402 | E16: HK | F16: 小米集团 | G16: 1810 | H16: 卖出 | I16: -5000 | L16: 15.8 | M16: =L16*I16 -> -79000
D17: 45409 | E17: HK | F17: 小米集团 | G17: 1810 | H17: 卖出 | I17: -1000 | L17: 17.36 | M17: =L17*I17 -> -17360
D18: 45416 | E18: HK | F18: 小米集团 | G18: 1810 | H18: 卖出 | I18: -2000 | L18: 18.18 | M18: =L18*I18 -> -36360
D19: 45437 | E19: HK | F19: 小米集团 | G19: 1810 | H19: 卖出 | I19: -2000 | L19: 18.3 | M19: =L19*I19 -> -36600
D20: 45423 | E20: US | F20: 超微电脑 | G20: SMCI | H20: 买入 | I20: 7 | L20: 6228.3 | M20: =L20*I20 -> 43598.1
D21: 45444 | E21: US | F21: 超微电脑 | G21: SMCI | H21: 买入 | I21: 3 | L21: 6119.178 | M21: =L21*I21 -> 18357.534
D22: 45472 | E22: US | F22: 超微电脑 | G22: SMCI | H22: 买入 | I22: 5 | L22: 6390.93 | M22: =L22*I22 -> 31954.65
D23: 45479 | E23: US | F23: 超微电脑 | G23: SMCI | H23: 买入 | I23: 5 | L23: 6603.324 | M23: =L23*I23 -> 33016.62
D24: 45486 | E24: US | F24: 超微电脑 | G24: SMCI | H24: 卖出 | I24: -10 | L24: 7097.688 | M24: =L24*I24 -> -70976.88
D25: 45493 | E25: US | F25: 超微电脑 | G25: SMCI | H25: 买入 | I25: 5 | L25: 6214.884 | M25: =L25*I25 -> 31074.42
D26: 45566 | E26: US | F26: 超微电脑 | G26: SMCI | H26: 拆股 | I26: =250-25 -> 225 | M26: =L26*I26 -> 0
D27: 45591 | E27: US | F27: 超微电脑 | G27: SMCI | H27: 买入 | I27: 100 | L27: 368.706 | M27: =L27*I27 -> 36870.6
D28: 45598 | E28: US | F28: 超微电脑 | G28: SMCI | H28: 卖出 | I28: -350 | L28: 203.19 | M28: =L28*I28 -> -71116.5
D29: 45514 | E29: US | F29: 超微电脑 | G29: SMCI | H29: 买入 | I29: 10 | L29: 3968.328 | M29: =L29*I29 -> 39683.28
D30: 45416 | E30: US | F30: 微软 | G30: MSFT | H30: 买入 | I30: 10 | L30: 3171.948 | M30: =L30*I30 -> 31719.48
D31: 45444 | E31: US | F31: 微软 | G31: MSFT | H31: 买入 | I31: 5 | L31: 3238.014 | M31: =L31*I31 -> 16190.07
D32: 45465 | E32: US | F32: 微软 | G32: MSFT | H32: 卖出 | I32: -5 | L32: 3508.284 | M32: =L32*I32 -> -17541.42
D33: 45486 | E33: US | F33: 微软 | G33: MSFT | H33: 买入 | I33: 5 | L33: 3537.69 | M33: =L33*I33 -> 17688.45
D34: 45591 | E34: US | F34: 微软 | G34: MSFT | H34: 卖出 | I34: -15 | L34: 3339.57 | M34: =L34*I34 -> -50093.55
D35: 45381 | E35: US | F35: 安森美半导体 | G35: ON | H35: 买入 | I35: 50 | L35: 573.69 | M35: =L35*I35 -> 28684.5
D36: 45416 | E36: US | F36: 安森美半导体 | G36: ON | H36: 买入 | I36: 30 | L36: 548.886 | M36: =L36*I36 -> 16466.58
D37: 45409 | E37: US | F37: 安森美半导体 | G37: ON | H37: 买入 | I37: 10 | L37: 530.868 | M37: =L37*I37 -> 5308.68
D38: 45423 | E38: US | F38: 安森美半导体 | G38: ON | H38: 卖出 | I38: -90 | L38: 549.588 | M38: =L38*I38 -> -49462.92
... D57: 45710 | E57: US | F57: 谷歌 | G57: GOOGL | H57: 卖出 | I57: -42 | L57: 1401.348 | M57: =L57*I57 -> -58856.616
C58: 4 | D58: 45157 | E58: CN | F58: 比亚迪 | G58: 002594 | H58: 买入 | I58: 100 | L58: 240.29 | M58: =L58*I58 -> 24029
...

Sheet 彩银
A1: back | D1: 操盘：周彩银
D2: 时间 | E2: 市场 | F2: 企业 | G2: 股票代码 | H2: 操作 | I2: 数量 | J2: 平均买价 | K2: 成本 | L2: 买卖价格 | M2: 市值
C3: 1 | D3: 45969 | E3: CN | F3: 中芯国际 | G3: 688981 | H3: 买入 | I3: 1000 | L3: 122.11 | M3: =L3*I3 -> 122110
C4: 2 | D4: 45969 | E4: US | F4: 特斯拉 | G4: TSLA | H4: 买入 | I4: 100 | L4: 3350.256 | M4: =L4*I4 -> 335025.6
C5: 3 | D5: 45976 | E5: CN | F5: 比亚迪 | G5: 002594 | H5: 买入 | I5: 1000 | L5: 98.37 | M5: =L5*I5 -> 98370
C6: 4 | D6: 45976 | E6: CN | F6: 海天味业 | G6: 603288 | H6: 买入 | I6: 1000 | L6: 38.42 | M6: =L6*I6 -> 38420
C7: 5 | M7: =L7*I7 -> 0
C8: 6 | M8: =L8*I8 -> 0
C9: 7 | M9: =L9*I9 -> 0
C10: 8 | M10: =L10*I10 -> 0
C11: 9 | M11: =L11*I11 -> 0
C12: 10 | M12: =L12*I12 -> 0
D13: 累计净买入 | M13: =SUM(M3:M12) -> 593925.6
D14: 时间 | E14: 市场 | F14: 企业 | G14: 股票代码 | H14: 状态 | I14: 数量 | J14: 平均买价 | K14: 成本 | L14: 当前股价 | M14: 市值
D15: =全班!$R$1 -> 46011 | E15: CN | F15: 中芯国际 | G15: 688981 | H15: 持有 | I15: =SUMIFS($I$3:$I$13,$G$3:$G$13,G15) -> 1000 | J15: =K15/I15 -> 122.11 | K15: =SUMIFS($M$3:$M$13,$G$3:$G$13,G15) -> 122110 | L15: =VLOOKUP(G15,股价!C:D,2,FALSE) -> 113.63 | M15: =IFERROR(I15*L15,0) -> 113630
D16: =全班!$R$1 -> 46011 | E16: US | F16: 特斯拉 | G16: TSLA | H16: 持有 | I16: =SUMIFS($I$3:$I$13,$G$3:$G$13,G16) -> 100 | J16: =K16/I16 -> 3350.256 | K16: =SUMIFS($M$3:$M$13,$G$3:$G$13,G16) -> 335025.6 | L16: =VLOOKUP(G16,股价!C:D,2,FALSE) -> 3753.36 | M16: =IFERROR(I16*L16,0) -> 375336
D17: =全班!$R$1 -> 46011 | E17: CN | F17: 比亚迪 | G17: 002594 | H17: 持有 | I17: =SUMIFS($I$3:$I$13,$G$3:$G$13,G17) -> 1000 | J17: =K17/I17 -> 98.37 | K17: =SUMIFS($M$3:$M$13,$G$3:$G$13,G17) -> 98370 | L17: =VLOOKUP(G17,股价!C:D,2,FALSE) -> 94.23 | M17: =IFERROR(I17*L17,0) -> 94230
D18: =全班!$R$1 -> 46011 | E18: CN | F18: 海天味业 | G18: 603288 | H18: 持有 | I18: =SUMIFS($I$3:$I$13,$G$3:$G$13,G18) -> 1000 | J18: =K18/I18 -> 38.42 | K18: =SUMIFS($M$3:$M$13,$G$3:$G$13,G18) -> 38420 | L18: =VLOOKUP(G18,股价!C:D,2,FALSE) -> 37.78 | M18: =IFERROR(I18*L18,0) -> 37780
D19: =全班!$R$1 -> 46011 | H19: 持有 | I19: =SUMIFS($I$3:$I$13,$G$3:$G$13,G19) -> 0 | J19: =K19/I19 -> #DIV/0! | K19: =SUMIFS($M$3:$M$13,$G$3:$G$13,G19) -> 0 | L19: =VLOOKUP(G19,股价!C:D,2,FALSE) -> #N/A | M19: =IFERROR(I19*L19,0) -> 0
D21: 市值结余 | M21: =SUM(M15:M20) -> 620976
D22: 累计分红 | M22: =L35 -> 0
D23: 现金结余 | M23: =M28-M13+M22 -> 406074.4
D24: 结余总额 | M24: =M21+M23 -> 1027050.4
D25: 累计盈利 | M25: =M24-M28 -> 27050.4
D26: 盈利率 | M26: =M25/M28 -> 0.0270504
D28: 本金 | M28: =本金与余额!D25 -> 1000000
D29: 登记日 | E29: 市场 | F29: 企业 | G29: 股票代码 | H29: 状态 | I29: 数量 | J29: 分红方案 | K29: 实施 | L29: 红利金额 | M29: 除权日
D35: 累计分红 | L35: =SUM(L30:L34) -> 0

Sheet 俊峰
A1: back | D1: 操盘：邹俊峰
D2: 时间 | E2: 市场 | F2: 企业 | G2: 股票代码 | H2: 操作 | I2: 数量 | J2: 平均买价 | K2: 成本 | L2: 买卖价格 | M2: 市值
C3: 1 | D3: 45143 | E3: CN | F3: 科大讯飞 | G3: 002230 | H3: 卖出 | I3: -2000 | L3: 63.32 | M3: =L3*I3 -> -126640
C4: 2 | D4: 45136 | E4: CN | F4: 科大讯飞 | G4: 002230 | H4: 买入 | I4: 2000 | L4: 62.43 | M4: =L4*I4 -> 124860
C5: 3 | D5: 45143 | E5: CN | F5: 英杰电气 | G5: 300820 | H5: 卖出 | I5: -1000 | L5: =股价!D78 -> 38.34 | M5: =L5*I5 -> -38340
C6: 4 | D6: 45136 | E6: CN | F6: 英杰电气 | G6: 300820 | H6: 买入 | I6: 1000 | L6: 68.65 | M6: =L6*I6 -> 68650
C7: 5 | D7: 45143 | E7: CN | F7: 特一药业 | G7: 002728 | H7: 买入 | I7: 8000 | L7: 15.51 | M7: =L7*I7 -> 124080
C8: 6 | D8: 45150 | E8: CN | F8: 特一药业 | G8: 002728 | H8: 卖出 | I8: -8000 | L8: 16.74 | M8: =L8*I8 -> -133920
C9: 7 | D9: 45143 | E9: CN | F9: 东田微 | G9: 301183 | H9: 买入 | I9: 1000 | L9: 52.04 | M9: =L9*I9 -> 52040
C10: 8 | D10: 45150 | E10: CN | F10: 东田微 | G10: 301183 | H10: 买入 | I10: 3000 | L10: 48.89 | M10: =L10*I10 -> 146670
C11: 9 | D11: 45185 | E11: CN | F11: 东田微 | G11: 301183 | H11: 卖出 | I11: -4000 | L11: 50.7 | M11: =L11*I11 -> -202800
C12: 10 | D12: 45185 | E12: CN | F12: 姚记科技 | G12: 002605 | H12: 卖出 | I12: -3000 | L12: 26.34 | M12: =L12*I12 -> -79020
C13: 11 | D13: 45150 | E13: CN | F13: 姚记科技 | G13: 002605 | H13: 买入 | I13: 3000 | L13: 33.43 | M13: =L13*I13 -> 100290
C14: 12 | D14: 45136 | E14: CN | F14: 中船科技 | G14: 600072 | H14: 买入 | I14: 3000 | L14: 24.62 | M14: =L14*I14 -> 73860
C15: 13 | D15: 45143 | E15: CN | F15: 中船科技 | G15: 600072 | H15: 买入 | I15: 3000 | L15: 23.13 | M15: =L15*I15 -> 69390
C16: 14 | D16: 45150 | E16: CN | F16: 中船科技 | G16: 600072 | H16: 买入 | I16: 8000 | L16: 22.02 | M16: =L16*I16 -> 176160
C17: 15 | D17: 45192 | E17: CN | F17: 中船科技 | G17: 600072 | H17: 卖出 | I17: -14000 | L17: 19.84 | M17: =L17*I17 -> -277760
C18: 16 | D18: 45136 | E18: CN | F18: 西安饮食 | G18: 000721 | H18: 买入 | I18: 8000 | L18: 13.91 | M18: =L18*I18 -> 111280
C19: 17 | D19: 45150 | E19: CN | F19: 西安饮食 | G19: 000721 | H19: 买入 | I19: 2000 | L19: 14.04 | M19: =L19*I19 -> 28080
C20: 18 | D20: 45213 | E20: CN | F20: 西安饮食 | G20: 000721 | H20: 卖出 | I20: -10000 | L20: 11.45 | M20: =L20*I20 -> -114500
C21: 19 | D21: 45164 | E21: CN | F21: 首创证券 | G21: 601136 | H21: 买入 | I21: 4000 | L21: 25.27 | M21: =L21*I21 -> 101080
C22: 20 | D22: 45185 | E22: CN | F22: 首创证券 | G22: 601136 | H22: 买入 | I22: 2000 | L22: 22.25 | M22: =L22*I22 -> 44500
C23: 21 | D23: 45213 | E23: CN | F23: 首创证券 | G23: 601136 | H23: 卖出 | I23: -6000 | L23: 20.42 | M23: =L23*I23 -> -122520
C24: 22 | D24: 45276 | E24: CN | F24: 宝明科技 | G24: 002992 | H24: 买入 | I24: 905 | L24: 75.06 | M24: =L24*I24 -> 67929.3
C25: 23 | D25: 45290 | E25: CN | F25: 翠微股份 | G25: 603123 | H25: 买入 | I25: 5000 | L25: 10.65 | M25: =L25*I25 -> 53250
C26: 24 | D26: 45290 | E26: CN | F26: 科大讯飞 | G26: 002230 | H26: 买入 | I26: 1811 | L26: 46.38 | M26: =L26*I26 -> 83994.18
C27: 25 | D27: 45353 | E27: CN | F27: 宝明科技 | G27: 002992 | H27: 卖出 | I27: -905 | L27: 49.97 | M27: =L27*I27 -> -45222.85
C28: 26 | D28: 45353 | E28: CN | F28: 富春股份 | G28: 300299 | H28: 卖出 | I28: -10000 | L28: 4.94 | M28: =L28*I28 -> -49400
C29: 27 | D29: 45353 | E29: CN | F29: 翠微股份 | G29: 603123 | H29: 卖出 | I29: -11020 | L29: 8.59 | M29: =L29*I29 -> -94661.8
C30: 28 | D30: 45353 | E30: CN | F30: 科大讯飞 | G30: 002230 | H30: 卖出 | I30: -1811 | L30: 52.57 | M30: =L30*I30 -> -95204.27
C31: 29 | D31: 45283 | E31: CN | F31: 富春股份 | G31: 300299 | H31: 买入 | I31: 10000 | L31: 5.89 | M31: =L31*I31 -> 58900
C32: 30 | D32: 45283 | E32: CN | F32: 翠微股份 | G32: 603123 | H32: 买入 | I32: 6020 | L32: 10.4 | M32: =L32*I32 -> 62608
C33: 31 | D33: 45136 | E33: CN | F33: 中科曙光 | G33: 603019 | H33: 买入 | I33: 3000 | L33: 45.15 | M33: =L33*I33 -> 135450
C34: 32 | D34: 45192 | E34: CN | F34: 中科曙光 | G34: 603019 | H34: 买入 | I34: 1000 | L34: 39.13 | M34: =L34*I34 -> 39130
C35: 33 | D35: 45255 | E35: CN | F35: 中科曙光 | G35: 603019 | H35: 卖出 | I35: -4000 | L35: 38 | M35: =L35*I35 -> -152000
C36: 34 | D36: 45192 | E36: CN | F36: 剑桥科技 | G36: 603083 | H36: 买入 | I36: 3000 | L36: 48.1 | M36: =L36*I36 -> 144300
C37: 35 | D37: 45227 | E37: CN | F37: 剑桥科技 | G37: 603083 | H37: 买入 | I37: 764 | L37: 36.96 | M37: =L37*I37 -> 28237.44
C38: 36 | D38: 45247 | E38: CN | F38: 剑桥科技 | G38: 603083 | H38: 卖出 | I38: -2000 | L38: 43.48 | M38: =L38*I38 -> -86960
C39: 37 | D39: 45276 | E39: CN | F39: 剑桥科技 | G39: 603083 | H39: 卖出 | I39: -1764 | L39: 40.85 | M39: =L39*I39 -> -72059.4
C40: 38 | D40: 45255 | E40: US | F40: 蔚来 | G40: NIO | H40: 买入 | I40: 3758 | L40: 57.72 | M40: =L40*I40 -> 216911.76
...

Sheet 怡锋
A1: back | D1: 操盘：骆怡锋
D2: 时间 | E2: 市场 | F2: 企业 | G2: 股票代码 | H2: 操作 | I2: 数量 | J2: 平均买价 | K2: 成本 | L2: 买卖价格 | M2: 市值
C3: 2 | D3: 45150 | E3: HK | F3: 中芯国际 | G3: 981 | H3: 买入 | I3: 10000 | L3: 18.1 | M3: =L3*I3 -> 181000
C4: 8 | D4: 45241 | E4: HK | F4: 中芯国际 | G4: 981 | H4: 卖出 | I4: -10000 | L4: 21.8 | M4: =L4*I4 -> -218000
C5: 5 | D5: 45185 | E5: CN | F5: 浪潮信息 | G5: 000977 | H5: 买入 | I5: 8000 | L5: 35.82 | M5: =L5*I5 -> 286560
C6: 6 | D6: 45220 | E6: CN | F6: 浪潮信息 | G6: 000977 | H6: 买入 | I6: 1600 | L6: 29.65 | M6: =L6*I6 -> 47440
C7: 9 | D7: 45241 | E7: CN | F7: 钧达股份 | G7: 002865 | H7: 买入 | I7: 2000 | L7: 95.26 | M7: =L7*I7 -> 190520
C8: 10 | D8: 45241 | E8: CN | F8: 润和软件 | G8: 300339 | H8: 买入 | I8: 12879 | L8: 27.15 | M8: =L8*I8 -> 349664.85
C9: 9 | D9: 45367 | E9: CN | F9: 浪潮信息 | G9: 000977 | H9: 卖出 | I9: -5000 | L9: 39.98 | M9: =L9*I9 -> -199900
D10: 45367 | E10: CN | F10: 博创科技 | G10: 300548 | H10: 买入 | I10: 6704 | L10: 29.82 | M10: =L10*I10 -> 199913.28
D11: 45500 | E11: CN | F11: 浪潮信息 | G11: 000977 | H11: 卖出 | I11: -4600 | L11: 37.1 | M11: =L11*I11 -> -170660
D12: 45500 | E12: CN | F12: 钧达股份 | G12: 002865 | H12: 卖出 | I12: -2000 | L12: 36.81 | M12: =L12*I12 -> -73620
D13: 45500 | E13: CN | F13: 润和软件 | G13: 300339 | H13: 卖出 | I13: -12879 | L13: 20.04 | M13: =L13*I13 -> -258095.16
D14: 45500 | E14: CN | F14: 博创科技 | G14: 300548 | H14: 卖出 | I14: -6704 | L14: 17.79 | M14: =L14*I14 -> -119264.16
C15: 1 | D15: 45136 | E15: HK | F15: 小米集团 | G15: 01810 | H15: 买入 | I15: 20000 | L15: 12.18 | M15: =L15*I15 -> 243600
C16: 3 | D16: 45164 | E16: HK | F16: 小米集团 | G16: 01810 | H16: 买入 | I16: 10000 | L16: 12.1 | M16: =L16*I16 -> 121000
C17: 4 | D17: 45178 | E17: HK | F17: 小米集团 | G17: 01810 | H17: 买入 | I17: 10000 | L17: 11.9 | M17: =L17*I17 -> 119000
D18: 45500 | E18: US | F18: 超微电脑 | G18: SMCI | H18: 买入 | I18: 111 | L18: 5555.082 | M18: =L18*I18 -> 616614.1
D19: 45566 | E19: US | F19: 超微电脑 | G19: SMCI | H19: 拆股 | I19: 999 | M19: =L19*I19 -> 0
D20: 45241 | E20: HK | F20: 小米集团 | G20: 01810 | H20: 卖出 | I20: -20000 | L20: 16.04 | M20: =L20*I20 -> -320800
D21: 45661 | E21: HK | F21: 小米集团 | G21: 01810 | H21: 卖出 | I21: -5000 | L21: 36.25 | M21: =L21*I21 -> -181250
D22: 45661 | E22: US | F22: 超微电脑 | G22: SMCI | H22: 买入 | I22: 716 | L22: 259.974 | M22: =L22*I22 -> 186141.38
D23: 45710 | E23: HK | F23: 小米集团 | G23: 01810 | H23: 卖出 | I23: -8000 | L23: 51.7 | M23: =L23*I23 -> -413600
D24: 45710 | E24: US | F24: 超微电脑 | G24: SMCI | H24: 卖出 | I24: -800 | L24: 437.346 | M24: =L24*I24 -> -349876.8
D25: 45710 | E25: CN | F25: 贵州茅台 | G25: 600519 | H25: 买入 | I25: 200 | L25: 1488.21 | M25: =L25*I25 -> 297642
D26: 45717 | E26: US | F26: 超微电脑 | G26: SMCI | H26: 买入 | I26: 300 | L26: 323.388 | M26: =L26*I26 -> 97016.4
D27: 45724 | E27: US | F27: 超微电脑 | G27: SMCI | H27: 买入 | I27: 400 | L27: 298.272 | M27: =L27*I27 -> 119308.8
D28: 45724 | E28: CN | F28: 包钢股份 | G28: 600010 | H28: 买入 | I28: 60000 | L28: 1.86 | M28: =L28*I28 -> 111600
D29: 45724 | E29: CN | F29: 易华录 | G29: 300212 | H29: 买入 | I29: 4000 | L29: 28.08 | M29: =L29*I29 -> 112320
D30: 45731 | E30: CN | F30: 包钢股份 | G30: 600010 | H30: 卖出 | I30: -30000 | L30: 1.9 | M30: =L30*I30 -> -57000
D31: 45731 | E31: CN | F31: 酒鬼酒 | G31: 000799 | H31: 买入 | I31: 1594 | L31: 51.88 | M31: =L31*I31 -> 82696.72
... D41: 45913 | E41: US | F41: 消费ETF龙头 | G41: 560680 | H41: 买入 | I41: 50000 | L41: 0.963 | M41: =L41*I41 -> 48150
M42: =L42*I42 -> 0
C43: 10 | M43: =L43*I43 -> 0
D44: 累计净买入 | M44: =SUM(M3:M43) -> 890920.97
C45: 骆怡锋 | D45: 时间 | E45: 市场 | F45: 企业 | G45: 股票代码 | H45: 状态 | I45: 数量 | J45: 平均买价 | K45: 成本 | L45: 当前价格 | M45: 市值
D46: =全班!$R$1 -> 46011 | E46: HK | F46: 小米集团 | G46: 01810 | H46: 持有 | I46: =SUMIFS($I$15:$I$44,$G$15:$G$44,G46) -> 7000 | J46: =K46/I46 -> -61.721429 | K46: =SUMIFS($M$15:$M$44,$G$15:$G$44,G46) -> -432050 | L46: =VLOOKUP(G46,股价!C:D,2,FALSE) -> 40.54 | M46: =IFERROR(I46*L46,0) -> 283780
D47: =全班!$R$1 -> 46011 | E47: US | F47: 超微电脑 | G47: SMCI | H47: 持有 | I47: =SUMIFS($I$15:$I$44,$G$15:$G$44,G47) -> 919 | J47: =K47/I47 -> 336.34678 | K47: =SUMIFS($M$15:$M$44,$G$15:$G$44,G47) -> 309102.69 | L47: =VLOOKUP(G47,股价!C:D,2,FALSE) -> 242.658 | M47: =IFERROR(I47*L47,0) -> 223002.7
D48: =全班!$R$1 -> 46011 | E48: CN | F48: 贵州茅台 | G48: 600519 | H48: 持有 | I48: =SUMIFS($I$15:$I$44,$G$15:$G$44,G48) -> 100 | J48: =K48/I48 -> 1391.21 | K48: =SUMIFS($M$15:$M$44,$G$15:$G$44,G48) -> 139121 | L48: =VLOOKUP(G48,股价!C:D,2,FALSE) -> 1410 | M48: =IFERROR(I48*L48,0) -> 141000
D49: =全班!$R$1 -> 46011 | E49: CN | F49: 包钢股份 | G49: 600010 | H49: 持有 | I49: =SUMIFS($I$15:$I$44,$G$15:$G$44,G49) -> 30000 | J49: =K49/I49 -> 1.82 | K49: =SUMIFS($M$15:$M$44,$G$15:$G$44,G49) -> 54600 | L49: =VLOOKUP(G49,股价!C:D,2,FALSE) -> 2.37 | M49: =IFERROR(I49*L49,0) -> 71100
...

Sheet 闯振
A1: back | D1: 操盘：候闯振
D2: 时间 | E2: 市场 | F2: 企业 | G2: 股票代码 | H2: 操作 | I2: 数量 | J2: 平均买价 | K2: 成本 | L2: 买卖价格 | M2: 市值
C3: 1 | D3: 45136 | E3: US | F3: 亚马逊 | G3: AMZN | H3: 买入 | I3: 225 | L3: 1031.238 | M3: =L3*I3 -> 232028.55
C4: 2 | D4: 45220 | E4: US | F4: 亚马逊 | G4: AMZN | H4: 卖出 | I4: -145 | L4: 976.326 | M4: =L4*I4 -> -141567.27
C5: 3 | D5: 45247 | E5: US | F5: 亚马逊 | G5: AMZN | H5: 卖出 | I5: -80 | L5: 1132.404 | M5: =L5*I5 -> -90592.32
C6: 4 | D6: 45220 | E6: US | F6: 英伟达 | G6: NVDA | H6: 买入 | I6: 25 | L6: 3228.186 | M6: =L6*I6 -> 80704.65
C7: 5 | D7: 45247 | E7: US | F7: 英伟达 | G7: NVDA | H7: 卖出 | I7: -25 | L7: 3845.244 | M7: =L7*I7 -> -96131.1
C8: 8 | D8: 45136 | E8: HK | F8: 腾讯集团 | G8: 00700 | H8: 买入 | I8: 800 | L8: 350.4 | M8: =L8*I8 -> 280320
C9: 9 | D9: 45220 | E9: HK | F9: 腾讯集团 | G9: 00700 | H9: 卖出 | I9: -800 | L9: 289 | M9: =L9*I9 -> -231200
C10: 6 | D10: 45136 | E10: US | F10: 阿里巴巴 | G10: BABA | H10: 买入 | I10: 400 | L10: 784.29 | M10: =L10*I10 -> 313716
C11: 7 | D11: 45136 | E11: HK | F11: 碧桂园 | G11: 02007 | H11: 买入 | I11: 100169 | L11: 1.69 | M11: =L11*I11 -> 169285.61
C12: 10 | D12: 45220 | E12: HK | F12: 碧桂园 | G12: 02007 | H12: 卖出 | I12: -100169 | L12: 0.75 | M12: =L12*I12 -> -75126.75
D13: 45276 | E13: US | F13: 阿里巴巴 | G13: BABA | H13: 卖出 | I13: -300 | L13: 581.178 | M13: =L13*I13 -> -174353.4
D14: 45276 | E14: HK | F14: 东方甄选 | G14: 1797 | H14: 买入 | I14: 6700 | L14: 26.25 | M14: =L14*I14 -> 175875
D15: 45283 | E15: HK | F15: 东方甄选 | G15: 1797 | H15: 卖出 | I15: -6700 | L15: 28.85 | M15: =L15*I15 -> -193295
D16: 45283 | E16: HK | F16: 腾讯集团 | G16: 00700 | H16: 买入 | I16: 705 | L16: 274 | M16: =L16*I16 -> 193170
D17: 45479 | E17: US | F17: 阿里巴巴 | G17: BABA | H17: 卖出 | I17: -100 | L17: 581.256 | M17: =L17*I17 -> -58125.6
D18: 45479 | E18: HK | F18: 腾讯集团 | G18: 00700 | H18: 卖出 | I18: -705 | L18: 379.8 | M18: =L18*I18 -> -267759
D19: 45479 | E19: US | F19: 耐克 | G19: NKE | H19: 买入 | I19: 454 | L19: 588.354 | M19: =L19*I19 -> 267112.72
D20: 45507 | E20: US | F20: 耐克 | G20: NKE | H20: 卖出 | I20: -454 | L20: 577.278 | M20: =L20*I20 -> -262084.21
C21: 11 | D21: 45220 | E21: US | F21: 特斯拉 | G21: TSLA | H21: 买入 | I21: 223 | L21: 1653.522 | M21: =L21*I21 -> 368735.41
C22: 12 | D22: 45247 | E22: US | F22: 特斯拉 | G22: TSLA | H22: 买入 | I22: 103 | L22: 1827.54 | M22: =L22*I22 -> 188236.62
D23: 45479 | E23: US | F23: 英伟达 | G23: NVDA | H23: 买入 | I23: 60 | L23: 981.474 | M23: =L23*I23 -> 58888.44
D24: 45507 | E24: US | F24: 亚马逊 | G24: AMZN | H24: 买入 | I24: 200 | L24: 1309.62 | M24: =L24*I24 -> 261924
D25: 45528 | E25: US | F25: 英伟达 | G25: NVDA | H25: 卖出 | I25: -60 | L25: 1009.086 | M25: =L25*I25 -> -60545.16
D26: 45528 | E26: US | F26: 特斯拉 | G26: TSLA | H26: 卖出 | I26: -326 | L26: 1718.496 | M26: =L26*I26 -> -560229.7
D27: 45528 | E27: US | F27: 亚马逊 | G27: AMZN | H27: 卖出 | I27: -200 | L27: 1380.912 | M27: =L27*I27 -> -276182.4
D28: 45542 | E28: US | F28: 特斯拉 | G28: TSLA | H28: 买入 | I28: 272 | L28: 1643.694 | M28: =L28*I28 -> 447084.77
D29: 45542 | E29: US | F29: 英伟达 | G29: NVDA | H29: 买入 | I29: 561 | L29: 802.074 | M29: =L29*I29 -> 449963.51
D30: 45556 | E30: US | F30: 特斯拉 | G30: TSLA | H30: 卖出 | I30: -272 | L30: 1858.35 | M30: =L30*I30 -> -505471.2
D31: 45556 | E31: US | F31: 英伟达 | G31: NVDA | H31: 卖出 | I31: -561 | L31: 904.8 | M31: =L31*I31 -> -507592.8
D32: 45556 | E32: CN | F32: 药明康德 | G32: 603259 | H32: 买入 | I32: 24968 | L32: 40.58 | M32: =L32*I32 -> 1013201.4
D33: 45577 | E33: CN | F33: 药明康德 | G33: 603259 | H33: 卖出 | I33: -24968 | L33: 51.45 | M33: =L33*I33 -> -1284603.6
D34: 45710 | E34: US | F34: 英伟达 | G34: NVDA | H34: 买入 | I34: 1186 | L34: 1083.03 | M34: =L34*I34 -> 1284473.6
... D38: 45976 | E38: US | F38: 特斯拉 | G38: TSLA | H38: 买入 | I38: 591 | L38: 3153.93 | M38: =L38*I38 -> 1863972.6
M39: =L39*I39 -> 0
M40: =L40*I40 -> 0
M41: =L41*I41 -> 0
M42: =L42*I42 -> 0
M43: =L43*I43 -> 0
...

Sheet 天明
A1: back | D1: 操盘：杨天明 | O1: 操盘：杨天明
D2: 时间 | E2: 市场 | F2: 企业 | G2: 股票代码 | H2: 操作 | I2: 数量 | J2: 平均买价 | K2: 成本 | L2: 买卖价格 | M2: 市值 | O2: 时间 | P2: 市场 | Q2: 企业 | R2: 股票代码 | S2: 操作 | T2: 数量 | U2: 平均买价 | V2: 成本 | W2: 买卖价格 | X2: 市值
C3: 1 | M3: =L3*I3 -> 0 | X3: =W3*T3 -> 0
C4: 2 | M4: =L4*I4 -> 0 | X4: =W4*T4 -> 0
C5: 3 | M5: =L5*I5 -> 0 | X5: =W5*T5 -> 0
C6: 4 | M6: =L6*I6 -> 0 | X6: =W6*T6 -> 0
C7: 5 | M7: =L7*I7 -> 0 | X7: =W7*T7 -> 0
C8: 6 | M8: =L8*I8 -> 0 | X8: =W8*T8 -> 0
C9: 7 | M9: =L9*I9 -> 0 | X9: =W9*T9 -> 0
C10: 8 | M10: =L10*I10 -> 0 | X10: =W10*T10 -> 0
C11: 9 | M11: =L11*I11 -> 0 | X11: =W11*T11 -> 0
C12: 10 | M12: =L12*I12 -> 0 | X12: =W12*T12 -> 0
D13: 累计净买入 | M13: =SUM(M3:M12) -> 0 | O13: 累计净买入 | X13: =SUM(X3:X12) -> 0
D14: 时间 | E14: 市场 | F14: 企业 | G14: 股票代码 | H14: 状态 | I14: 数量 | J14: 平均买价 | K14: 成本 | L14: 当前股价 | M14: 市值 | O14: 时间 | P14: 市场 | Q14: 企业 | R14: 股票代码 | S14: 状态 | T14: 数量 | U14: 平均买价 | V14: 成本 | W14: 当前股价 | X14: 市值
D15: =全班!$R$1 -> 46011 | H15: 持有 | I15: =SUMIFS($I$3:$I$13,$G$3:$G$13,G15) -> 0 | J15: =K15/I15 -> #DIV/0! | K15: =SUMIFS($M$3:$M$13,$G$3:$G$13,G15) -> 0 | L15: =VLOOKUP(G15,股价!C:D,2,FALSE) -> #N/A | M15: =IFERROR(I15*L15,0) -> 0 | O15: =全班!$R$1 -> 46011 | S15: 持有 | T15: =SUMIFS($I$3:$I$13,$G$3:$G$13,R15) -> 0 | U15: =V15/T15 -> #DIV/0! | V15: =SUMIFS($X$3:$X$13,$R$3:$R$13,R15) -> 0 | W15: =VLOOKUP(R15,股价!C:D,2,FALSE) -> #N/A | X15: =T15*W15 -> #N/A
D19: 市值结余 | M19: =SUM(M15:M18) -> 0 | O19: 市值结余 | X19: =SUM(X15:X18) -> #N/A
D20: 累计分红 | M20: =L33 -> 0 | O20: 累计分红 | X20: =W33 -> 0
D21: 现金结余 | M21: =M26-M13+M20 -> 1000000 | O21: 现金结余 | X21: =X26-X13+X20 -> #REF!
D22: 结余总额 | M22: =M19+M21 -> 1000000 | O22: 结余总额 | X22: =X19+X21 -> #N/A
D23: 累计盈利 | M23: =M22-M26 -> 0 | O23: 累计盈利 | X23: =X22-X26 -> #N/A
D24: 盈利率 | M24: =M23/M26 -> 0 | O24: 盈利率 | X24: =X23/X26 -> #N/A
D26: 本金 | M26: =本金与余额!D15 -> 1000000 | O26: 本金 | X26: =本金与余额!#REF! -> #REF!
D27: 登记日 | E27: 市场 | F27: 企业 | G27: 股票代码 | H27: 状态 | I27: 数量 | J27: 分红方案 | K27: 实施 | L27: 红利金额 | M27: 除权日 | O27: 登记日 | P27: 市场 | Q27: 企业 | R27: 股票代码 | S27: 状态 | T27: 数量 | U27: 分红方案 | V27: 实施 | W27: 红利金额 | X27: 除权日
D33: 累计分红 | L33: =SUM(L28:L32) -> 0 | O33: 累计分红 | W33: =SUM(W28:W32) -> 0

Sheet 小林
A1: back | D1: 操盘：纪小林
D2: 时间 | E2: 市场 | F2: 企业 | G2: 股票代码 | H2: 操作 | I2: 数量 | J2: 平均买价 | K2: 成本 | L2: 买卖价格 | M2: 市值
C3: 1 | D3: 45906 | E3: US | F3: 拼多多 | G3: PDD | H3: 买入 | I3: 1026 | L3: 972.504 | M3: =L3*I3 -> 997789.1
C4: 2 | D4: 45997 | E4: US | F4: 拼多多 | G4: PDD | H4: 卖出 | I4: -526 | L4: 917.47149 | M4: =L4*I4 -> -482590
C5: 3 | D5: 45997 | E5: US | F5: 拼多多-期权 | G5: PDD-C130-2026-4-17 | H5: 买入 | I5: 13400 | L5: 35.88 | M5: =L5*I5 -> 480792
C6: 4 | M6: =L6*I6 -> 0
C7: 5 | M7: =L7*I7 -> 0
C8: 6 | M8: =L8*I8 -> 0
C9: 7 | M9: =L9*I9 -> 0
C10: 8 | M10: =L10*I10 -> 0
C11: 9
C12: 10
D13: 累计净买入 | M13: =SUM(M3:M12) -> 995991.1
D14: 时间 | E14: 市场 | F14: 企业 | G14: 股票代码 | H14: 状态 | I14: 数量 | J14: 平均买价 | K14: 成本 | L14: 当前价格 | M14: 市值
D15: =全班!$R$1 -> 46011 | E15: US | F15: 拼多多 | G15: PDD | I15: =SUMIFS($I$3:$I$13,$G$3:$G$13,G15) -> 500 | J15: =K15/I15 -> 1030.3982 | K15: =SUMIFS($M$3:$M$13,$G$3:$G$13,G15) -> 515199.1 | L15: =VLOOKUP(G15,股价!C:D,2,FALSE) -> 854.178 | M15: =IFERROR(I15*L15,0) -> 427089
D16: =全班!$R$1 -> 46011 | E16: US | F16: 拼多多-期权 | G16: PDD-C130-2026-4-17 | I16: =SUMIFS($I$3:$I$13,$G$3:$G$13,G16) -> 13400 | J16: =K16/I16 -> 35.88 | K16: =SUMIFS($M$3:$M$13,$G$3:$G$13,G16) -> 480792 | L16: =VLOOKUP(G16,股价!C:D,2,FALSE) -> 20.982 | M16: =IFERROR(I16*L16,0) -> 281158.8
D19: 市值结余 | M19: =SUM(M15:M18) -> 708247.8
D20: 累计分红 | M20: =L33 -> 0
D21: 现金结余 | M21: =M26-M13+M20 -> 4008.8997
D22: 结余总额 | M22: =M19+M21 -> 712256.7
D23: 累计盈利 | M23: =M22-M26 -> -287743.3
D24: 盈利率 | M24: =M23/M26 -> -0.2877433
D26: 本金 | M26: =本金与余额!D16 -> 1000000
D27: 登记日 | E27: 市场 | F27: 企业 | G27: 股票代码 | H27: 状态 | I27: 数量 | J27: 分红方案 | K27: 实施 | L27: 红利金额 | M27: 除权日
D33: 累计分红 | L33: =SUM(L28:L32) -> 0

Sheet 秀容
A1: back | D1: 操盘：高秀容 | O1: 操盘：高秀容
D2: 时间 | E2: 市场 | F2: 企业 | G2: 股票代码 | H2: 操作 | I2: 数量 | J2: 平均买价 | K2: 成本 | L2: 买卖价格 | M2: 市值 | O2: 时间 | P2: 市场 | Q2: 企业 | R2: 股票代码 | S2: 操作 | T2: 数量 | U2: 平均买价 | V2: 成本 | W2: 买卖价格 | X2: 市值
C3: 1 | M3: =L3*I3 -> 0 | X3: =W3*T3 -> 0
C4: 2 | M4: =L4*I4 -> 0 | X4: =W4*T4 -> 0
C5: 3
C6: 4
C7: 5
C8: 6 | M8: =L8*I8 -> 0 | X8: =W8*T8 -> 0
C9: 7
C10: 8
C11: 9 | M11: =L11*I11 -> 0 | X11: =W11*T11 -> 0
C12: 10 | M12: =L12*I12 -> 0 | X12: =W12*T12 -> 0
D13: 累计净买入 | M13: =SUM(M3:M12) -> 0 | O13: 累计净买入 | X13: =SUM(X3:X12) -> 0
D14: 时间 | E14: 市场 | F14: 企业 | G14: 股票代码 | H14: 状态 | I14: 数量 | J14: 平均买价 | K14: 成本 | L14: 当前股价 | M14: 市值 | O14: 时间 | P14: 市场 | Q14: 企业 | R14: 股票代码 | S14: 状态 | T14: 数量 | U14: 平均买价 | V14: 成本 | W14: 当前股价 | X14: 市值
D15: =全班!$R$1 -> 46011 | I15: =SUMIFS($I$3:$I$13,$G$3:$G$13,G15) -> 0 | J15: =K15/I15 -> #DIV/0! | K15: =SUMIFS($M$3:$M$13,$G$3:$G$13,G15) -> 0 | L15: =VLOOKUP(G15,股价!C:D,2,FALSE) -> #N/A | M15: =IFERROR(I15*L15,0) -> 0 | O15: =全班!$R$1 -> 46011 | T15: =SUMIFS($I$3:$I$13,$G$3:$G$13,R15) -> 0 | U15: =V15/T15 -> #DIV/0! | V15: =SUMIFS($X$3:$X$13,$R$3:$R$13,R15) -> 0 | W15: =VLOOKUP(R15,股价!C:D,2,FALSE) -> #N/A | X15: =T15*W15 -> #N/A
D19: 市值结余 | M19: =SUM(M15:M18) -> 0 | O19: 市值结余 | X19: =SUM(X15:X18) -> #N/A
D20: 累计分红 | M20: =L33 -> 0 | O20: 累计分红 | X20: =W33 -> 0
D21: 现金结余 | M21: =M26-M13+M20 -> 1000000 | O21: 现金结余 | X21: =X26-X13+X20 -> #REF!
D22: 结余总额 | M22: =M19+M21 -> 1000000 | O22: 结余总额 | X22: =X19+X21 -> #N/A
D23: 累计盈利 | M23: =M22-M26 -> 0 | O23: 累计盈利 | X23: =X22-X26 -> #N/A
D24: 盈利率 | M24: =M23/M26 -> 0 | O24: 盈利率 | X24: =X23/X26 -> #N/A
D26: 本金 | M26: =本金与余额!D17 -> 1000000 | O26: 本金 | X26: =本金与余额!#REF! -> #REF!
D27: 登记日 | E27: 市场 | F27: 企业 | G27: 股票代码 | H27: 状态 | I27: 数量 | J27: 分红方案 | K27: 实施 | L27: 红利金额 | M27: 除权日 | O27: 登记日 | P27: 市场 | Q27: 企业 | R27: 股票代码 | S27: 状态 | T27: 数量 | U27: 分红方案 | V27: 实施 | W27: 红利金额 | X27: 除权日
D33: 累计分红 | L33: =SUM(L28:L32) -> 0 | O33: 累计分红 | W33: =SUM(W28:W32) -> 0

Sheet 艺娜
A1: back | D1: 操盘：赵艺娜
D2: 时间 | E2: 市场 | F2: 企业 | G2: 股票代码 | H2: 操作 | I2: 数量 | J2: 平均买价 | K2: 成本 | L2: 买卖价格 | M2: 市值
C3: 1 | D3: 45976 | E3: CN | F3: 亿帆医药 | G3: 002019 | H3: 买入 | I3: 1000 | L3: 13.16 | M3: =L3*I3 -> 13160
C4: 2 | D4: 45976 | E4: CN | F4: 中金公司 | G4: 601995 | H4: 买入 | I4: 1000 | L4: 35.41 | M4: =L4*I4 -> 35410
C5: 3 | D5: 45976 | E5: CN | F5: 东方精工 | G5: 002611 | H5: 买入 | I5: 1000 | L5: 18.02 | M5: =L5*I5 -> 18020
C6: 4 | M6: =L6*I6 -> 0
C7: 5 | M7: =L7*I7 -> 0
C8: 6 | M8: =L8*I8 -> 0
C9: 7 | M9: =L9*I9 -> 0
C10: 8 | M10: =L10*I10 -> 0
C11: 9 | M11: =L11*I11 -> 0
C12: 10 | M12: =L12*I12 -> 0
D13: 累计净买入 | M13: =SUM(M3:M12) -> 66590
D14: 时间 | E14: 市场 | F14: 企业 | G14: 股票代码 | H14: 状态 | I14: 数量 | J14: 平均买价 | K14: 成本 | L14: 当前股价 | M14: 市值
D15: =全班!$R$1 -> 46011 | E15: CN | F15: 亿帆医药 | G15: 002019 | H15: 持有 | I15: =SUMIFS($I$3:$I$13,$G$3:$G$13,G15) -> 1000 | J15: =K15/I15 -> 13.16 | K15: =SUMIFS($M$3:$M$13,$G$3:$G$13,G15) -> 13160 | L15: =VLOOKUP(G15,股价!C:D,2,FALSE) -> 12 | M15: =IFERROR(I15*L15,0) -> 12000
D16: =全班!$R$1 -> 46011 | E16: CN | F16: 中金公司 | G16: 601995 | H16: 持有 | I16: =SUMIFS($I$3:$I$13,$G$3:$G$13,G16) -> 1000 | J16: =K16/I16 -> 35.41 | K16: =SUMIFS($M$3:$M$13,$G$3:$G$13,G16) -> 35410 | L16: =VLOOKUP(G16,股价!C:D,2,FALSE) -> 35.92 | M16: =IFERROR(I16*L16,0) -> 35920
D17: =全班!$R$1 -> 46011 | E17: CN | F17: 东方精工 | G17: 002611 | H17: 持有 | I17: =SUMIFS($I$3:$I$13,$G$3:$G$13,G17) -> 1000 | J17: =K17/I17 -> 18.02 | K17: =SUMIFS($M$3:$M$13,$G$3:$G$13,G17) -> 18020 | L17: =VLOOKUP(G17,股价!C:D,2,FALSE) -> 17.68 | M17: =IFERROR(I17*L17,0) -> 17680
D22: 市值结余 | M22: =SUM(M15:M21) -> 65600
D23: 累计分红 | M23: =L36 -> 0
D24: 现金结余 | M24: =M29-M13+M23 -> 933410
D25: 结余总额 | M25: =M22+M24 -> 999010
D26: 累计盈利 | M26: =M25-M29 -> -990
D27: 盈利率 | M27: =M26/M29 -> -0.00099
D29: 本金 | M29: =本金与余额!D14 -> 1000000
D30: 登记日 | E30: 市场 | F30: 企业 | G30: 股票代码 | H30: 状态 | I30: 数量 | J30: 分红方案 | K30: 实施 | L30: 红利金额 | M30: 除权日
D36: 累计分红 | L36: =SUM(L31:L35) -> 0

Sheet 季生
A1: back | D1: 操盘：季院生
D2: 时间 | E2: 市场 | F2: 企业 | G2: 股票代码 | H2: 操作 | I2: 数量 | J2: 平均买价 | K2: 成本 | L2: 买卖价格 | M2: 市值
C3: 1 | D3: 45150 | E3: HK | F3: 山东黄金 | G3: 1787 | H3: 买入 | I3: 2500 | L3: 15.3 | M3: =L3*I3 -> 38250
C4: 2 | D4: 45157 | E4: HK | F4: 山东黄金 | G4: 1787 | H4: 买入 | I4: 3000 | L4: 14.9 | M4: =L4*I4 -> 44700
C5: 3 | D5: 45178 | E5: CN | F5: 比亚迪 | G5: 002594 | H5: 买入 | I5: 3757 | L5: 244.05 | M5: =L5*I5 -> 916895.85
C6: 4 | D6: 45353 | E6: CN | F6: 比亚迪 | G6: 002594 | H6: 卖出 | I6: -3757 | L6: 192.18 | M6: =L6*I6 -> -722020.26
C7: 5 | D7: 45353 | E7: HK | F7: 山东黄金 | G7: 1787 | H7: 买入 | I7: 55637 | L7: 12.98 | M7: =L7*I7 -> 722168.26
C8: 6 | D8: 45395 | E8: HK | F8: 山东黄金 | G8: 1787 | H8: 卖出 | I8: -61137 | L8: 19.66 | M8: =L8*I8 -> -1201953.4
C9: 7 | D9: 45395 | E9: CN | F9: 同花顺 | G9: 300033 | H9: 买入 | I9: 3200 | L9: 112.91 | M9: =L9*I9 -> 361312
C10: 8 | D10: 45409 | E10: CN | F10: 同花顺 | G10: 300033 | H10: 买入 | I10: 2085 | L10: 121 | M10: =L10*I10 -> 252285
C11: 9 | D11: 45437 | E11: CN | F11: 同花顺 | G11: 300033 | H11: 买入 | I11: 5140 | L11: 114.46 | M11: =L11*I11 -> 588324.4
D12: 45542 | E12: CN | F12: 同花顺 | G12: 300033 | H12: 卖出 | I12: -10425 | L12: 99.6 | M12: =L12*I12 -> -1038330
D13: 45542 | E13: US | F13: 英伟达 | G13: NVDA | H13: 买入 | I13: 1294 | L13: 802.074 | M13: =L13*I13 -> 1037883.8
D14: 45612 | E14: US | F14: 英伟达 | G14: NVDA | H14: 卖出 | I14: -1294 | L14: 1107.444 | M14: =L14*I14 -> -1433032.5
D15: 45612 | E15: HK | F15: 山东黄金 | G15: 01787 | H15: 买入 | I15: 106502 | L15: 13.46 | M15: =L15*I15 -> 1433516.9
D16: 45640 | E16: HK | F16: 山东黄金 | G16: 01787 | H16: 卖出 | I16: -106502 | L16: 13.54 | M16: =L16*I16 -> -1442037.1
D17: 45640 | E17: US | F17: 谷歌 | G17: GOOGL | H17: 买入 | I17: 973 | L17: 1481.376 | M17: =L17*I17 -> 1441378.8
D18: 45752 | E18: US | F18: 谷歌 | G18: GOOGL | H18: 卖出 | I18: -486 | L18: 1135.68 | M18: =L18*I18 -> -551940.48
D19: 45752 | E19: US | F19: 纳斯达克100三倍做空 | G19: SQQQ | H19: 买入 | I19: 703 | L19: 392.808 | M19: =L19*I19 -> 276144.02
D20: 45759 | E20: US | F20: 纳斯达克100三倍做空 | G20: SQQQ | H20: 卖出 | I20: -703 | L20: 282.516 | M20: =L20*I20 -> -198608.75
D21: 45759 | E21: US | F21: 丰田工业ADR | G21: TYIDY | H21: 买入 | I21: 419 | L21: 659.802 | M21: =L21*I21 -> 276457.04
D22: 45787 | E22: US | F22: 谷歌 | G22: GOOGL | H22: 卖出 | I22: -243 | L22: 1191.45 | M22: =L22*I22 -> -289522.35
D23: 45794 | E23: US | F23: 谷歌 | G23: GOOGL | H23: 卖出 | I23: -244 | L23: 1296.282 | M23: =L23*I23 -> -316292.81
... D52: 46011 | E52: US | F52: 英伟达 | G52: NVDA | H52: 买入 | I52: 355 | L52: 1411.722 | M52: =L52*I52 -> 501161.31
M53: =L53*I53 -> 0
M54: =L54*I54 -> 0
M55: =L55*I55 -> 0
M56: =L56*I56 -> 0
M57: =L57*I57 -> 0
C58: 10 | M58: =L58*I58 -> 0
D59: 累计净买入 | M59: =SUM(M3:M58) -> -24432.978
D60: 时间 | E60: 市场 | F60: 企业 | G60: 股票代码 | H60: 状态 | I60: 数量 | J60: 平均买价 | K60: 成本 | L60: 当前价格 | M60: 市值
D61: =全班!$R$1 -> 46011 | E61: US | F61: 甲骨文 | G61: ORCL | H61: 持有 | I61: =SUMIFS($I$51:$I$59,$G$51:$G$59,G61) -> 333 | J61: =K61/I61 -> 1497.366 | K61: =SUMIFS($M$51:$M$59,$G$51:$G$59,G61) -> 498622.88 | L61: =VLOOKUP(G61,股价!C:D,2,FALSE) -> 1497.366 | M61: =IFERROR(I61*L61,0) -> 498622.88
D62: =全班!$R$1 -> 46011 | E62: US | F62: 英伟达 | G62: NVDA | H62: 持有 | I62: =SUMIFS($I$51:$I$59,$G$51:$G$59,G62) -> 355 | J62: =K62/I62 -> 1411.722 | K62: =SUMIFS($M$51:$M$59,$G$51:$G$59,G62) -> 501161.31 | L62: =VLOOKUP(G62,股价!C:D,2,FALSE) -> 1411.722 | M62: =IFERROR(I62*L62,0) -> 501161.31
D63: =全班!$R$1 -> 46011 | H63: 持有 | I63: =SUMIFS($I$51:$I$59,$G$51:$G$59,G63) -> 0 | J63: =K63/I63 -> #DIV/0! | K63: =SUMIFS($M$51:$M$59,$G$51:$G$59,G63) -> 0 | L63: =VLOOKUP(G63,股价!C:D,2,FALSE) -> #N/A | M63: =IFERROR(I63*L63,0) -> 0
M64: =IFERROR(I64*L64,0) -> 0
D65: 市值结余 | M65: =SUM(M61:M64) -> 999784.19
D66: 累计分红 | M66: =L79 -> 0
D67: 现金结余 | M67: =M72-M59+M66 -> 1024433
D68: 结余总额 | M68: =M65+M67 -> 2024217.2
...

Sheet 万辉
A1: back | D1: 操盘：于万辉
D2: 时间 | E2: 市场 | F2: 企业 | G2: 股票代码 | H2: 操作 | I2: 数量 | J2: 平均买价 | K2: 成本 | L2: 买卖价格 | M2: 市值
C3: 1 | D3: 45136 | E3: CN | F3: 证券ETF | G3: 512880 | H3: 买入 | I3: 400000 | L3: 1.017 | M3: =L3*I3 -> 406800
C4: 2 | D4: 45157 | E4: CN | F4: 证券ETF | G4: 512880 | H4: 卖出 | I4: -200000 | L4: 1.021 | M4: =L4*I4 -> -204200
C5: 3 | D5: 45255 | E5: CN | F5: 证券ETF | G5: 512880 | H5: 卖出 | I5: -200000 | L5: 0.957 | M5: =L5*I5 -> -191400
C6: 4 | D6: 45255 | E6: CN | F6: 智飞生物 | G6: 300122 | H6: 买入 | I6: 1000 | L6: 66.12 | M6: =L6*I6 -> 66120
C7: 5 | D7: 45283 | E7: CN | F7: 智飞生物 | G7: 300122 | H7: 卖出 | I7: -1000 | L7: 57.79 | M7: =L7*I7 -> -57790
C8: 6 | D8: 45136 | E8: US | F8: 英伟达 | G8: NVDA | H8: 买入 | I8: 2 | L8: =467.5*7.8 -> 3646.5 | M8: =L8*I8 -> 7293
C9: 7 | D9: 45150 | E9: US | F9: 英伟达 | G9: NVDA | H9: 卖出 | I9: -2 | L9: 3186.69 | M9: =L9*I9 -> -6373.38
C10: 8 | D10: 45136 | E10: HK | F10: 中芯国际 | G10: 981 | H10: 买入 | I10: 1000 | L10: 19.62 | M10: =L10*I10 -> 19620
C11: 9 | D11: 45178 | E11: HK | F11: 中芯国际 | G11: 981 | H11: 卖出 | I11: -1000 | L11: 19.8 | M11: =L11*I11 -> -19800
C12: 10 | D12: 45136 | E12: HK | F12: 融创中国 | G12: 1918 | H12: 买入 | I12: 10000 | L12: 1.38 | M12: =L12*I12 -> 13800
C13: 11 | D13: 45178 | E13: HK | F13: 融创中国 | G13: 1918 | H13: 卖出 | I13: -10000 | L13: 2.48 | M13: =L13*I13 -> -24800
C14: 12 | D14: 45136 | E14: CN | F14: 华熙生物 | G14: 688363 | H14: 买入 | I14: 1000 | L14: 96.97 | M14: =L14*I14 -> 96970
C15: 13 | D15: 45178 | E15: CN | F15: 华熙生物 | G15: 688363 | H15: 卖出 | I15: -1000 | L15: 89 | M15: =L15*I15 -> -89000
C16: 14 | D16: 45164 | E16: CN | F16: 中国平安 | G16: 601318 | H16: 买入 | I16: 5000 | L16: 47.01 | M16: =L16*I16 -> 235050
C17: 15 | D17: 45178 | E17: CN | F17: 中国平安 | G17: 601318 | H17: 卖出 | I17: -4000 | L17: 50.12 | M17: =L17*I17 -> -200480
C18: 16 | D18: 45234 | E18: CN | F18: 中国平安 | G18: 601318 | H18: 买入 | I18: 3000 | L18: 45.24 | M18: =L18*I18 -> 135720
C19: 17 | D19: 45290 | E19: CN | F19: 中国平安 | G19: 601318 | H19: 卖出 | I19: -4000 | L19: 40.3 | M19: =L19*I19 -> -161200
C20: 18 | D20: 45192 | E20: CN | F20: 万泰生物 | G20: 603392 | H20: 买入 | I20: 8000 | L20: 48.71 | M20: =L20*I20 -> 389680
C21: 19 | D21: 45290 | E21: CN | F21: 万泰生物 | G21: 603392 | H21: 卖出 | I21: -4000 | L21: 75.13 | M21: =L21*I21 -> -300520
... C24: 22 | D24: 45178 | E24: CN | F24: 宁德时代 | G24: 300750 | H24: 卖出 | I24: -900 | L24: 222.94 | M24: =L24*I24 -> -200646
C25: 23 | D25: =全班!$R$1 -> 46011 | E25: CN | F25: 宁德时代 | G25: 300750 | H25: 买入 | I25: 1691 | L25: 156.29 | M25: =L25*I25 -> 264286.39
C26: 24 | D26: 45346 | E26: CN | F26: 宁德时代 | G26: 300750 | H26: 卖出 | I26: -1791 | L26: 160.5 | M26: =L26*I26 -> -287455.5
C27: 25 | D27: 45290 | E27: CN | F27: 上海沪工 | G27: 603131 | H27: 买入 | I27: 10000 | L27: 14.76 | M27: =L27*I27 -> 147600
C28: 26 | D28: 45304 | E28: CN | F28: 上海沪工 | G28: 603131 | H28: 买入 | I28: 5000 | L28: 15.32 | M28: =L28*I28 -> 76600
C29: 27 | D29: 45360 | E29: CN | F29: 上海沪工 | G29: 603131 | H29: 卖出 | I29: -15000 | L29: 19.07 | M29: =L29*I29 -> -286050
C30: 28 | D30: 45360 | E30: CN | F30: 罗欣药业 | G30: 002793 | H30: 买入 | I30: 30000 | L30: 4.52 | M30: =L30*I30 -> 135600
C31: 29 | D31: 45367 | E31: CN | F31: 罗欣药业 | G31: 002793 | H31: 卖出 | I31: -30000 | L31: 4.13 | M31: =L31*I31 -> -123900
D32: 45409 | E32: CN | F32: 上海沪工 | G32: 603131 | H32: 买入 | I32: 5000 | L32: 13.18 | M32: =L32*I32 -> 65900
D33: 45437 | E33: CN | F33: 上海沪工 | G33: 603131 | H33: 卖出 | I33: -5000 | L33: 14.8 | M33: =L33*I33 -> -74000
D34: 45388 | E34: CN | F34: 明阳智能 | G34: 601615 | H34: 买入 | I34: 5000 | L34: 9.58 | M34: =L34*I34 -> 47900
D35: 45444 | E35: CN | F35: 明阳智能 | G35: 601615 | H35: 卖出 | I35: -5000 | L35: 10.17 | M35: =L35*I35 -> -50850
D36: 45444 | E36: CN | F36: 罗欣药业 | G36: 002793 | H36: 卖出 | I36: -10000 | L36: 4.8 | M36: =L36*I36 -> -48000
D37: 45388 | E37: CN | F37: 罗欣药业 | G37: 002793 | H37: 买入 | I37: 10000 | L37: 4.54 | M37: =L37*I37 -> 45400
D38: 45444 | E38: US | F38: 富时中国50三倍做空ETF | G38: YANG | H38: 买入 | I38: 300 | L38: 64.428 | M38: =L38*I38 -> 19328.4
D39: 45465 | E39: US | F39: 富时中国50三倍做空ETF | G39: YANG | H39: 卖出 | I39: -300 | L39: 65.364 | M39: =L39*I39 -> -19609.2
D40: 45367 | E40: US | F40: 苹果 | G40: AAPL | H40: 买入 | I40: 200 | L40: 1346.436 | M40: =L40*I40 -> 269287.2
D41: 45367 | E41: US | F41: 谷歌-A | G41: GOOGL | H41: 买入 | I41: 200 | L41: 1101.204 | M41: =L41*I41 -> 220240.8
D42: 45493 | E42: US | F42: 苹果 | G42: AAPL | H42: 卖出 | I42: -200 | L42: 1749.618 | M42: =L42*I42 -> -349923.6
...

Sheet 柯滔
A1: back | D1: 操盘：柯滔
D2: 时间 | E2: 市场 | F2: 企业 | G2: 股票代码 | H2: 操作 | I2: 数量 | J2: 平均买价 | K2: 成本 | L2: 买卖价格 | M2: 市值
D3: 45479 | E3: US | F3: 苹果 | G3: AAPL | H3: 买入 | I3: 50 | L3: 1765.452 | M3: =L3*I3 -> 88272.6
D4: 45521 | E4: US | F4: 苹果 | G4: AAPL | H4: 卖出 | I4: -50 | L4: 1763.19 | M4: =L4*I4 -> -88159.5
C5: 1 | D5: 45409 | E5: US | F5: 特斯拉 | G5: TSLA | H5: 买入 | I5: 200 | L5: 1312.662 | M5: =L5*I5 -> 262532.4
C6: 4 | D6: 45465 | E6: US | F6: 特斯拉 | G6: TSLA | H6: 买入 | I6: 50 | L6: 1427.478 | M6: =L6*I6 -> 71373.9
D7: 45493 | E7: US | F7: 特斯拉 | G7: TSLA | H7: 卖出 | I7: -100 | L7: 1865.76 | M7: =L7*I7 -> -186576
D8: 45577 | E8: US | F8: 特斯拉 | G8: TSLA | H8: 卖出 | I8: -140 | L8: 1698.84 | M8: =L8*I8 -> -237837.6
D9: 45591 | E9: US | F9: 特斯拉 | G9: TSLA | H9: 卖出 | I9: -10 | L9: 2099.682 | M9: =L9*I9 -> -20996.82
C10: 7 | D10: 45472 | E10: US | F10: 美国超微公司 | G10: AMD | H10: 买入 | I10: 50 | L10: 1265.238 | M10: =L10*I10 -> 63261.9
D11: 45591 | E11: US | F11: 美国超微公司 | G11: AMD | H11: 卖出 | I11: -50 | L11: 1218.594 | M11: =L11*I11 -> -60929.7
C12: 8 | D12: 45472 | E12: US | F12: 博通 | G12: AVGO | H12: 买入 | I12: 10 | L12: 12523.134 | M12: =L12*I12 -> 125231.34
D13: 45486 | E13: US | F13: 博通 | G13: AVGO | H13: 买入 | I13: 20 | L13: 13265.226 | M13: =L13*I13 -> 265304.52
D14: 45488 | E14: US | F14: 博通 | G14: AVGO | H14: 拆股 | I14: 270 | M14: =L14*I14 -> 0
D15: 45493 | E15: US | F15: 博通 | G15: AVGO | H15: 卖出 | I15: -200 | L15: 1227.33 | M15: =L15*I15 -> -245466
D16: 45577 | E16: US | F16: 博通 | G16: AVGO | H16: 卖出 | I16: -80 | L16: 1415.544 | M16: =L16*I16 -> -113243.52
D17: 45647 | E17: US | F17: 博通 | G17: AVGO | H17: 卖出 | I17: -20 | L17: 1722.162 | M17: =L17*I17 -> -34443.24
D18: 45500 | E18: US | F18: 阿斯麦 | G18: ASML | H18: 买入 | I18: 10 | L18: 6929.442 | M18: =L18*I18 -> 69294.42
D19: 45591 | E19: US | F19: 阿斯麦 | G19: ASML | H19: 买入 | I19: 14 | L19: 5551.26 | M19: =L19*I19 -> 77717.64
D20: 45619 | E20: US | F20: 阿斯麦 | G20: ASML | H20: 卖出 | I20: -24 | L20: 5248.464 | M20: =L20*I20 -> -125963.14
C21: 3 | D21: 45444 | E21: US | F21: 加拿大鹅 | G21: GOOS | H21: 买入 | I21: 100 | L21: 112.788 | M21: =L21*I21 -> 11278.8
D22: 45486 | E22: US | F22: 加拿大鹅 | G22: GOOS | H22: 买入 | I22: 100 | L22: 102.258 | M22: =L22*I22 -> 10225.8
D23: 45500 | E23: US | F23: 加拿大鹅 | G23: GOOS | H23: 卖出 | I23: -200 | L23: 88.92 | M23: =L23*I23 -> -17784
C24: 2 | D24: 45409 | E24: US | F24: 脸书 | G24: Meta | H24: 买入 | I24: 50 | L24: 3457.662 | M24: =L24*I24 -> 172883.1
D25: 45486 | E25: US | F25: 脸书 | G25: Meta | H25: 卖出 | I25: -50 | L25: 3891.186 | M25: =L25*I25 -> -194559.3
D26: 45710 | E26: US | F26: 谷歌-A | G26: GOOGL | H26: 买入 | I26: 100 | L26: 1401.348 | M26: =L26*I26 -> 140134.8
D27: 45766 | E27: US | F27: 谷歌-A | G27: GOOGL | H27: 卖出 | I27: -20 | L27: 1179.048 | M27: =L27*I27 -> -23580.96
D28: 45815 | E28: US | F28: 谷歌-A | G28: GOOGL | H28: 卖出 | I28: -80 | L28: 1354.704 | M28: =L28*I28 -> -108376.32
C29: 5 | D29: 45465 | E29: US | F29: 拼多多 | G29: PDD | H29: 买入 | I29: 10 | L29: 1122.108 | M29: =L29*I29 -> 11221.08
D30: 45647 | E30: US | F30: 拼多多 | G30: PDD | H30: 买入 | I30: 112 | L30: 776.178 | M30: =L30*I30 -> 86931.936
D31: 45703 | E31: US | F31: 拼多多 | G31: PDD | H31: 卖出 | I31: -22 | L31: 968.448 | M31: =L31*I31 -> -21305.856
D32: 45717 | E32: US | F32: 拼多多 | G32: PDD | H32: 卖出 | I32: -50 | L32: 886.782 | M32: =L32*I32 -> -44339.1
D33: 45731 | E33: US | F33: 拼多多 | G33: PDD | H33: 卖出 | I33: -50 | L33: 955.812 | M33: =L33*I33 -> -47790.6
D34: 45577 | E34: US | F34: 诺和诺德 | G34: NVO | H34: 买入 | I34: 50 | L34: 936.312 | M34: =L34*I34 -> 46815.6
D35: 45710 | E35: US | F35: 诺和诺德 | G35: NVO | H35: 买入 | I35: 50 | L35: 687.024 | M35: =L35*I35 -> 34351.2
D36: 45745 | E36: US | F36: 诺和诺德 | G36: NVO | H36: 卖出 | I36: -100 | L36: 540.54 | M36: =L36*I36 -> -54054
D37: 45500 | E37: US | F37: 台积电 | G37: TSM | H37: 买入 | I37: 50 | L37: 1263.132 | M37: =L37*I37 -> 63156.6
D38: 45577 | E38: US | F38: 台积电 | G38: TSM | H38: 卖出 | I38: -40 | L38: 1488.318 | M38: =L38*I38 -> -59532.72
D39: 45703 | E39: US | F39: 台积电 | G39: TSM | H39: 卖出 | I39: -3 | L39: 1590.42 | M39: =L39*I39 -> -4771.26
D40: 45745 | E40: US | F40: 台积电 | G40: TSM | H40: 卖出 | I40: -7 | L40: 1288.95 | M40: =L40*I40 -> -9022.65
...

Sheet A股行业分类
B3: 序号 | C3: 细分行业 | D3: 企业名称 | E3: 企业数量占比 | H3: 细分行业 | I3: 股票代码 | J3: 企业名称 | K3: 2023-10-13 收市价 | L3: 市盈(TTM) | M3: 市盈(动) | N3: 市盈(静) | O3: 总市值
B4: 1 | C4: IT设备 | D4: 63 | E4: =D4/$D$114 -> 0.011889036 | H4: IT设备 | I4: 000066 | J4: 中国长城 | K4: 12.23 | N4: 327.99 | O4: 394.52
B5: 2 | C5: 白酒 | D5: 20 | E5: =D5/$D$114 -> 0.003774297 | H5: IT设备 | I5: 000977 | J5: 浪潮信息 | K5: 35.24 | L5: 35.74 | M5: 79.74 | N5: 24.94 | O5: 518.78
B6: 3 | C6: 百货 | D6: 36 | E6: =D6/$D$114 -> 0.0067937347 | H6: IT设备 | I6: 000997 | J6: 新 大 陆 | K6: 18.78 | M6: 17.17 | O6: 193.82
B7: 4 | C7: 半导体 | D7: 168 | E7: =D7/$D$114 -> 0.031704095 | H7: IT设备 | I7: 001229 | J7: 魅视科技 | K7: 30.89 | L7: 37.62 | M7: 46.02 | N7: 36.43 | O7: 30.89
B8: 5 | C8: 保险 | D8: 6 | E8: =D8/$D$114 -> 0.0011322891 | H8: IT设备 | I8: 001339 | J8: 智微智能 | K8: 25.51 | L8: 74.03 | M8: 76.54 | N8: 53.37 | O8: 63.56
B9: 6 | C9: 玻璃 | D9: 18 | E9: =D9/$D$114 -> 0.0033968673 | H9: IT设备 | I9: 002152 | J9: 广电运通 | K9: 12.19 | L9: 34.08 | M9: 31.96 | N9: 36.59 | O9: 302.72
B10: 7 | C10: 仓储物流 | D10: 48 | E10: =D10/$D$114 -> 0.0090583129 | H10: IT设备 | I10: 002180 | J10: 纳思达 | K10: 26.66 | L10: 32.89 | M10: 53.78 | N10: 20.27 | O10: 377.58
B11: 8 | C11: 超市连锁 | D11: 9 | E11: =D11/$D$114 -> 0.0016984337 | H11: IT设备 | I11: 002197 | J11: 证通电子 | K11: 10.42 | M11: 141.14 | O11: 64.02
B12: 9 | C12: 出版业 | D12: 28 | E12: =D12/$D$114 -> 0.0052840159 | H12: IT设备 | I12: 002236 | J12: 大华股份 | K12: 22.14 | L12: 26.23 | M12: 18.46 | N12: 31.38 | O12: 729.4
B13: 10 | C13: 船舶 | D13: 12 | E13: =D13/$D$114 -> 0.0022645782 | H13: IT设备 | I13: 002308 | J13: 威创股份 | K13: 5.45 | L13: 107.97 | M13: 85.09 | N13: 117.8 | O13: 49.39
B14: 11 | C14: 电气设备 | D14: 316 | E14: =D14/$D$114 -> 0.059633893 | H14: IT设备 | I14: 002351 | J14: 漫步者 | K14: 17.12 | L14: 48.34 | M14: 43.67 | N14: 61.74 | O14: 152.22
